Workbook
Name скидка_на_VRF_Приточные_установки: #REF!
Name скидка_на_VRF_Приточные_установки: #REF!
Name скидка_на_VRF_Приточные_установки: #REF!
Name скидка_на_VRF_Приточные_установки: #REF!
Name скидка_на_VRF_Приточные_установки: #REF!
Name скидка_на_VRF_Приточные_установки: #REF!
Name скидка_на_VRF_Приточные_установки: #REF!
Name скидка_на_VRF_Приточные_установки: #REF!
Name скидка_на_VRF_Приточные_установки: #REF!
Name скидка_на_VRF_Приточные_установки: #REF!
Name скидка_на_VRF_Приточные_установки: #REF!
Name скидка_на_VRF_Приточные_установки: 'Скидка '!#REF!
Name скидка_на_VRF_Приточные_установки: #REF!

Sheet Скидка 
A2: ОБОРУДОВАНИЕ HISENSE
A3: Тип оборудования | D3: Ваша скидка от дилерской цены, %
A4: Бытовые INVERTER сплит-системы и сплит-системы с приточной вентиляцией | D4: 0
A5: Бытовые ON OFF сплит-системы | D5: 0
A6: Мульти сплит-системы FREE MATCH DC INVERTER | D6: 0
A7: Аксессуары RAC&LCAC&FM | D7: 0
A8: Полупромышленные сплит-системы HEAVY CLASSIC и HEAVY DC INVERTER | D8: 0
A9: Мобильные кондиционеры | D9: 0
A10: Бытовые осушители воздуха | D10: 0
A11: Очистители воздуха | D11: 0
A12: Аксессуары для мобильных кондиционеров | D12: 0
A13: =A5 -> Бытовые ON OFF сплит-системы | C13: =A4 -> Бытовые INVERTER сплит-системы и сплит-системы с приточной вентиляцией
A15: Полупромышленные сплит-системы HEAVY СLASSIC | C15: Полупромышленные сплит-системы HEAVY DC INVERTER
A17: Мульти сплит-системы FREE MATCH DC INVERTER | C17: Мобильные кондиционеры

Sheet КРАТКИЙ ПРАЙС СПЛИТЫ
B2: ПРАЙС-ЛИСТ ДЕЙСТВИТЕЛЕН С 01.01.2026
A3: НС-комплекта | B3: Модель | C3: Мощность,кВт | E3: Класс энергоэф-фективности | F3: Уров. Шума внутреннего блока ДБ(A) | G3: Габариты блока (ДхВхГ),мм | I3: Вес нетто, внутр / наруж., кг | J3: РРЦ,руб. | K3: РИЦ,руб. | L3: Дилерская цена,руб. | M3: Ваша Спец цена,руб
C4: охл. | D4: нагр. | G4: Внутренний | H4: Наружный | J4: Комплект | K4: Комплект | L4: Комплект | M4: Комплект
B5: СПЛИТ-СИСТЕМЫ ИНВЕРТОРНОГО ТИПА С ПРИТОЧНОЙ ВЕНТИЛЯЦИЕЙ
B6: AIRSENSATION SUPERIOR DC Inverter | L6: УЗНАТЬБОЛЬШЕ
A7: НС-1413600 | B7: AS-10UW4RXVQF00 | C7: 2,6(1,0-4,0) | D7: 3,2(1,6-4,2) | E7: A+++/A+++ | F7: 18/25/28/31/33/35/37 | G7: 978×313×217 | H7: 810×585×280 | I7: 13,5/33 | J7: 80990 | K7: 68690 | L7: 51200 | M7: =L7*(1-1*'Скидка '!D$4) -> 51200
A8: НС-1413603 | B8: AS-13UW4RXVQF00 | C8: 3,5(1,0-4,4) | D8: 4,2(1,6-4,8) | E8: A+++/A+++ | F8: 18/25/28,5/31/33,5/35,5/38 | G8: 978×313×217 | H8: 810×585×280 | I8: 13,5/33 | J8: 88990 | K8: 75490 | L8: 56200 | M8: =L8*(1-1*'Скидка '!D$4) -> 56200
B9: СПЛИТ-СИСТЕМЫ ИНВЕРТОРНОГО ТИПА
B10: VISION PRO SUPERIOR DC Inverter | L10: УЗНАТЬ БОЛЬШЕ
A11: НС-1601145 | B11: AS-10UW4RXVQH00A | C11: 2,60 (1,00-4,00) | D11: 3,20 (1,60-4,20) | E11: A+++/A+++ | F11: 18/20/22/27/30/31/33 | G11: 877×301×194 | H11: 810×585×280 | I11: 10/33 | J11: 88490 | K11: 74790 | L11: 56400 | M11: =L11*(1-1*'Скидка '!D$4) -> 56400
A12: НС-1601147 | B12: AS-13UW4RXVQH01 | C12: 3,50 (1,00-4,40) | D12: 4,20 (1,60-4,80) | E12: A+++/A+++ | F12: 18/20/22/27/30/31/33 | G12: 877×301×194 | H12: 810×585×280 | I12: 10/33 | J12: 94490 | K12: 79990 | L12: 60200 | M12: =L12*(1-1*'Скидка '!D$4) -> 60200
A13: НС-1716163 | B13: AS-18UW4RBVQH00 | C13: 5,00 (1,50-6,00) | D13: 5,20 (1,60-6,20) | E13: A++/A+++ | F13: 29/32/35/38/40/42/45 | G13: 877×301×194 | H13: 860×667×310 | I13: 10/39 | J13: 142990 | K13: 121390 | L13: 91500 | M13: =L13*(1-1*'Скидка '!D$4) -> 91500
B14: VISION PRO CARBON SUPERIOR DC Inverter | L14: УЗНАТЬ БОЛЬШЕ
A15: НС-1601149 | B15: AS-10UW4RXVQH00A(B) | C15: 2,60 (1,00-4,00) | D15: 3,20 (1,60-4,20) | E15: A+++/A+++ | F15: 18/20/22/27/30/31/33 | G15: 883×305×198 | H15: 810×585×280 | I15: 10/33 | J15: 102990 | K15: 87390 | L15: 65800 | M15: =L15*(1-1*'Скидка '!D$4) -> 65800
A16: НС-1601150 | B16: AS-13UW4RXVQH01(B) | C16: 3,50 (1,00-4,40) | D16: 4,20 (1,60-4,80) | E16: A+++/A+++ | F16: 18/20/22/27/30/31/33 | G16: 883×305×198 | H16: 810×585×280 | I16: 10/33 | J16: 111490 | K16: 94590 | L16: 71200 | M16: =L16*(1-1*'Скидка '!D$4) -> 71200
B17: PREMIUM Design SUPER DC Inverter 2023 | L17: УЗНАТЬ БОЛЬШЕ
A18: НС-1497190 | B18: AS-10UW4RVETG01 | C18: 2,6(0,8-3,5) | D18: 2,8(0,8-3,5) | E18: А++/А+ | F18: 22/27,5/29/30,5/32,5/35,5/38 | G18: 950x272x207 | H18: 715x482x240 | I18: 9/24 | J18: 49090 | K18: 41590 | L18: 30200 | M18: =L18*(1-1*'Скидка '!D$4) -> 30200
A19: НС-1497191 | B19: AS-13UW4RVETG01 | C19: 3,5(1,2-4,1) | D19: 4,0(1,6-4,3) | E19: А++/А+ | F19: 23/27,5/29/32/34/36,5/40,5 | G19: 950x272x207 | H19: 715x482x240 | I19: 9/25 | J19: 55390 | K19: 46990 | L19: 34200 | M19: =L19*(1-1*'Скидка '!D$4) -> 34200
A20: НС-1497192 | B20: AS-18UW4RXATG03 | C20: 5,0(1,0-6,0) | D20: 5,6(1,6-6,25) | E20: А++/А+ | F20: 29/33,5/36/38/40/42,5/43,5 | G20: 1050x320x235 | H20: 810x585x280 | I20: 12/33 | J20: 90690 | K20: 76890 | L20: 56200 | M20: =L20*(1-1*'Скидка '!D$4) -> 56200
B21: PREMIUM Design SUPER DC Inverter 2025 Wi-Fi | L21: УЗНАТЬ БОЛЬШЕ
A22: НС-1692504 | B22: AS-10UW4RVETG01 WI-FI | C22: 2,6(0,8-3,5) | D22: 2,8(0,8-3,5) | E22: А++/А+ | F22: 22/27,5/29/30,5/32,5/35,5/38 | G22: 950x272x207 | H22: 715x482x240 | I22: 9/24 | J22: 52090 | K22: 44190 | L22: 32900 | M22: =L22*(1-1*'Скидка '!D$4) -> 32900
A23: НС-1692506 | B23: AS-13UW4RVETG01 WI-FI | C23: 3,5(1,2-4,1) | D23: 4,0(1,6-4,3) | E23: А++/А+ | F23: 23/27,5/29/32/34/36,5/40,5 | G23: 950x272x207 | H23: 715x482x240 | I23: 9/25 | J23: 58790 | K23: 49790 | L23: 37100 | M23: =L23*(1-1*'Скидка '!D$4) -> 37100
A24: НС-1692510 | B24: AS-18UW4RXATG03 WI-FI | C24: 5,0(1,0-6,0) | D24: 5,6(1,6-6,25) | E24: А++/А+ | F24: 29/33,5/36/38/40/42,5/43,5 | G24: 1050x320x235 | H24: 810x585x280 | I24: 12/33 | J24: 95090 | K24: 80590 | L24: 59900 | M24: =L24*(1-1*'Скидка '!D$4) -> 59900
B25: CHAMPAGNE CRYSTAL SUPER DC Inverter A++ | L25: УЗНАТЬ БОЛЬШЕ
A26: НС-1474739 | B26: AS-10UW4RVETG01(C) | C26: 2,6(0,8-3,5) | D26: 2,8(0,8-3,5) | E26: А++/А+ | F26: 22/27,5/29/30,5/32,5/35,5/38 | G26: 950x272x207 | H26: 715x482x240 | I26: 9/24 | J26: 51590 | K26: 43690 | L26: 31500 | M26: =L26*(1-1*'Скидка '!D$4) -> 31500
A27: НС-1474740 | B27: AS-13UW4RVETG01(C) | C27: 3,5(1,2-4,1) | D27: 4,0(1,6-4,3) | E27: А++/А+ | F27: 23/27,5/29/32/34/36,5/40,5 | G27: 950x272x207 | H27: 715x482x240 | I27: 9/25 | J27: 54690 | K27: 46390 | L27: 33500 | M27: =L27*(1-1*'Скидка '!D$4) -> 33500
B28: CHAMPAGNE CRYSTAL SUPER DC Inverter A++ 2025 Wi-Fi | L28: УЗНАТЬ БОЛЬШЕ
A29: НС-1694109 | B29: AS-10UW4RVETG01(C) WI-FI | C29: 2,6(0,8-3,5) | D29: 2,8(0,8-3,5) | E29: А++/А+ | F29: 22/27,5/29/30,5/32,5/35,5/38 | G29: 950x272x207 | H29: 715x482x240 | I29: 9/24 | J29: 55690 | K29: 47190 | L29: 35000 | M29: =L29*(1-1*'Скидка '!D$4) -> 35000
A30: НС-1694110 | B30: AS-13UW4RVETG01(C) WI-FI | C30: 3,5(1,2-4,1) | D30: 4,0(1,6-4,3) | E30: А++/А+ | F30: 23/27,5/29/32/34/36,5/40,5 | G30: 950x272x207 | H30: 715x482x240 | I30: 9/25 | J30: 58990 | K30: 49990 | L30: 37200 | M30: =L30*(1-1*'Скидка '!D$4) -> 37200
B31: RED CRYSTAL SUPER DC Inverter A++ | L31: УЗНАТЬ БОЛЬШЕ
A32: НС-1415693 | B32: AS-10UW4RVETG00(R) | C32: 2,6(0,80-3,5) | D32: 2,8(0,8-3,5) | E32: А++/А+ | F32: 22/27,5/29/30,5/32,5/35,5/38 | G32: 950x272x207 | H32: 715x482x240 | I32: 8,5/28 | J32: 51590 | K32: 43690 | L32: 31500 | M32: =L32*(1-1*'Скидка '!D$4) -> 31500
A33: НС-1415694 | B33: AS-13UW4RVETG00(R) | C33: 3,5(1,2-4,1) | D33: 4,0(1,6-4,3) | E33: А++/А+ | F33: 23/27,5/29/31,6/34/36,5/40 | G33: 950x272x207 | H33: 715x482x240 | I33: 8,5/28 | J33: 54690 | K33: 46390 | L33: 33500 | M33: =L33*(1-1*'Скидка '!D$4) -> 33500
B34: BLACK CRYSTAL Super DC Inverter 2023 A++ | L34: УЗНАТЬ БОЛЬШЕ
A35: НС-1514699 | B35: AS-10UW4RVETG01(B) | C35: 2,8(1,6-3,3) | D35: 2,8(1,6-3,0) | E35: А++/А+ | F35: 22/27,5/29/30,5/32,5/35,5/38 | G35: 950x272x207 | H35: 715x482x240 | I35: 9/24 | J35: 51590 | K35: 43690 | L35: 31500 | M35: =L35*(1-1*'Скидка '!D$4) -> 31500
A36: НС-1514751 | B36: AS-13UW4RVETG01(B) | C36: 3,75(1,0-4,0) | D36: 3,9(1,2-4,1) | E36: А++/А+ | F36: 23/27,5/29/32/34/36,5/40,5 | G36: 950x272x207 | H36: 715x482x240 | I36: 9/25 | J36: 54690 | K36: 46390 | L36: 33500 | M36: =L36*(1-1*'Скидка '!D$4) -> 33500
B37: BLACK CRYSTAL Super DC Inverter 2025 Wi-Fi | L37: УЗНАТЬ БОЛЬШЕ
A38: НС-1694123 | B38: AS-10UW4RVETG01(B) WI-FI | C38: 2,8(1,6-3,3) | D38: 2,8(1,6-3,0) | E38: А++/А+ | F38: 22/27,5/29/30,5/32,5/35,5/38 | G38: 950x272x207 | H38: 715x482x240 | I38: 9/24 | J38: 55690 | K38: 47190 | L38: 35000 | M38: =L38*(1-1*'Скидка '!D$4) -> 35000
A39: НС-1694125 | B39: AS-13UW4RVETG01(B) WI-FI | C39: 3,75(1,0-4,0) | D39: 3,9(1,2-4,1) | E39: А++/А+ | F39: 23/27,5/29/32/34/36,5/40,5 | G39: 950x272x207 | H39: 715x482x240 | I39: 9/25 | J39: 58990 | K39: 49990 | L39: 37200 | M39: =L39*(1-1*'Скидка '!D$4) -> 37200
B40: SILVER CRYSTAL Super DC Inverter 2023 A++ | L40: УЗНАТЬ БОЛЬШЕ
A41: НС-1489628 | B41: AS-10UW4RVETG01(S) | C41: 2,8(1,6-3,3) | D41: 2,8(1,6-3,0) | E41: А++/А+ | F41: 22/27,5/29/30,5/32,5/35,5/38 | G41: 950x272x207 | H41: 715x482x240 | I41: 9/24 | J41: 51590 | K41: 43690 | L41: 31500 | M41: =L41*(1-1*'Скидка '!D$4) -> 31500
...

Sheet RAC ON-OFF
C2: ='КРАТКИЙ ПРАЙС СПЛИТЫ'!B2 -> ПРАЙС-ЛИСТ ДЕЙСТВИТЕЛЕН С 01.01.2026
A3: НС-комплекта | B3: Кодблока | C3: Артикул | D3: Модель | E3: РЕКОМЕНДОВАННО ДЛЯ ПРОДАЖИ НА МП | F3: Мощность, кВт | H3: Класс энергоэффективности | I3: Уров. Шума внутреннего блока дБ(A) | J3: Габариты блока (ШхВхГ), мм | K3: Вес нетто, внутр/наруж., кг | L3: РРЦ, руб | M3: РИЦ, руб | N3: Дилерская цена, руб. | O3: РРЦ, руб | P3: РИЦ, руб | Q3: Дилерская цена, руб. | R3: Ваша Спец цена, руб
F4: охл. | G4: нагр. | J4: Нетто | L4: Блок | M4: Блок | N4: Блок | Q4: Комплект | R4: Комплект
C5: NEO Premium Classic A 2025 WI-FI | Q5: УЗНАТЬ БОЛЬШЕ
G6: Энергоэффективность класса А | J6: 4D-AUTO Air | Q6: СМОТРЕТЬ ВИДЕО
G7: Wi-Fi управление (встроенный модуль)* | J7: Silver Ion фильтр**
G8: Cold Plasma Ion Generator** | J8: Фотокаталитический фильтр**
G9: Работа на охлаждение до -40С*** | J9: Дополнительная шумоизоляция компрессора
G10: *партии 2025 года **только модели 07k, 10k ***с зимним комплектом
C11: распродажа остатков без встроенного Wi-Fi
A12: НС-1275295 | B12: НС-1291489 | C12: AS-07HW4SYDTG035G | D12: =VLOOKUP($A12,'КРАТКИЙ ПРАЙС СПЛИТЫ'!$A:$M,2,0) -> AS-07HW4SYDTG035 | F12: =VLOOKUP($A12,'КРАТКИЙ ПРАЙС СПЛИТЫ'!$A:$M,3,0) -> 2.1 | G12: =VLOOKUP($A12,'КРАТКИЙ ПРАЙС СПЛИТЫ'!$A:$M,4,0) -> 2.2 | H12: =VLOOKUP($A12,'КРАТКИЙ ПРАЙС СПЛИТЫ'!$A:$M,5,0) -> А/А | I12: =VLOOKUP($A12,'КРАТКИЙ ПРАЙС СПЛИТЫ'!$A:$M,6,0) -> 26/26,5/29/33/36 | J12: =VLOOKUP($A12,'КРАТКИЙ ПРАЙС СПЛИТЫ'!$A:$M,7,0) -> 880x275x207 | K12: =VLOOKUP($A12,'КРАТКИЙ ПРАЙС СПЛИТЫ'!$A:$M,9,0) -> 7/21,5 | L12: =MROUND(O12*0.3,100) -> 8300 | M12: =MROUND(P12*0.3,100) -> 7000 | N12: =MROUND(Q12*0.3,100) -> 5100 | O12: =VLOOKUP($A12,'КРАТКИЙ ПРАЙС СПЛИТЫ'!$A:$M,10,0) -> 27690 | P12: =VLOOKUP($A12,'КРАТКИЙ ПРАЙС СПЛИТЫ'!$A:$M,11,0) -> 23490 | Q12: =VLOOKUP($A12,'КРАТКИЙ ПРАЙС СПЛИТЫ'!$A:$M,12,0) -> 16900 | R12: =Q12*(1-1*'Скидка '!D$5) -> 16900
B13: НС-1291490 | C13: AS-07HW4SYDTG035W | F13: 2.1 | G13: 3.1 | H13: А/А | J13: =VLOOKUP($A12,'КРАТКИЙ ПРАЙС СПЛИТЫ'!$A:$M,8,0) -> 660x482x240 | K13: А/А | L13: =O12-L12 -> 19390 | M13: =P12-M12 -> 16490 | N13: =Q12-N12 -> 11800
A14: НС-1187844 | B14: НС-1291491 | C14: AS-10HW4SYDTG5G | D14: =VLOOKUP($A14,'КРАТКИЙ ПРАЙС СПЛИТЫ'!$A:$M,2,0) -> AS-10HW4SYDTG5 | F14: =VLOOKUP($A14,'КРАТКИЙ ПРАЙС СПЛИТЫ'!$A:$M,3,0) -> 2.7 | G14: =VLOOKUP($A14,'КРАТКИЙ ПРАЙС СПЛИТЫ'!$A:$M,4,0) -> 2.75 | H14: =VLOOKUP($A14,'КРАТКИЙ ПРАЙС СПЛИТЫ'!$A:$M,5,0) -> А/А | I14: =VLOOKUP($A14,'КРАТКИЙ ПРАЙС СПЛИТЫ'!$A:$M,6,0) -> 31/31,5/34/37/37,5 | J14: =VLOOKUP($A14,'КРАТКИЙ ПРАЙС СПЛИТЫ'!$A:$M,7,0) -> 880x275x207 | K14: =VLOOKUP($A14,'КРАТКИЙ ПРАЙС СПЛИТЫ'!$A:$M,9,0) -> 8/24 | L14: =MROUND(O14*0.3,100) -> 9000 | M14: =MROUND(P14*0.3,100) -> 7600 | N14: =MROUND(Q14*0.3,100) -> 5600 | O14: =VLOOKUP($A14,'КРАТКИЙ ПРАЙС СПЛИТЫ'!$A:$M,10,0) -> 30090 | P14: =VLOOKUP($A14,'КРАТКИЙ ПРАЙС СПЛИТЫ'!$A:$M,11,0) -> 25490 | Q14: =VLOOKUP($A14,'КРАТКИЙ ПРАЙС СПЛИТЫ'!$A:$M,12,0) -> 18500 | R14: =Q14*(1-1*'Скидка '!D$5) -> 18500
B15: НС-1291492 | C15: AS-10HW4SYDTGW | F15: 2.1 | G15: 3.1 | H15: А/А | J15: =VLOOKUP($A14,'КРАТКИЙ ПРАЙС СПЛИТЫ'!$A:$M,8,0) -> 660x482x240 | K15: А/А | L15: =O14-L14 -> 21090 | M15: =P14-M14 -> 17890 | N15: =Q14-N14 -> 12900
A16: НС-1187845 | B16: НС-1291498 | C16: AS-13HW4SVDTG5G | D16: =VLOOKUP($A16,'КРАТКИЙ ПРАЙС СПЛИТЫ'!$A:$M,2,0) -> AS-13HW4SVDTG5 | F16: =VLOOKUP($A16,'КРАТКИЙ ПРАЙС СПЛИТЫ'!$A:$M,3,0) -> 3.7 | G16: =VLOOKUP($A16,'КРАТКИЙ ПРАЙС СПЛИТЫ'!$A:$M,4,0) -> 3.75 | H16: =VLOOKUP($A16,'КРАТКИЙ ПРАЙС СПЛИТЫ'!$A:$M,5,0) -> А/А | I16: =VLOOKUP($A16,'КРАТКИЙ ПРАЙС СПЛИТЫ'!$A:$M,6,0) -> 32/32,5/34/36,5/37 | J16: =VLOOKUP($A16,'КРАТКИЙ ПРАЙС СПЛИТЫ'!$A:$M,7,0) -> 880x275x207 | K16: =VLOOKUP($A16,'КРАТКИЙ ПРАЙС СПЛИТЫ'!$A:$M,9,0) -> 8,4/27 | L16: =MROUND(O16*0.3,100) -> 12400 | M16: =MROUND(P16*0.3,100) -> 10500 | N16: =MROUND(Q16*0.3,100) -> 7600 | O16: =VLOOKUP($A16,'КРАТКИЙ ПРАЙС СПЛИТЫ'!$A:$M,10,0) -> 41290 | P16: =VLOOKUP($A16,'КРАТКИЙ ПРАЙС СПЛИТЫ'!$A:$M,11,0) -> 34990 | Q16: =VLOOKUP($A16,'КРАТКИЙ ПРАЙС СПЛИТЫ'!$A:$M,12,0) -> 25300 | R16: =Q16*(1-1*'Скидка '!D$5) -> 25300
B17: НС-1291501 | C17: AS-13HW4SVDTGW | F17: 2.1 | G17: 3.1 | H17: А/А | J17: =VLOOKUP($A16,'КРАТКИЙ ПРАЙС СПЛИТЫ'!$A:$M,8,0) -> 715x482x240 | K17: А/А | L17: =O16-L16 -> 28890 | M17: =P16-M16 -> 24490 | N17: =Q16-N16 -> 17700
A18: НС-1447629 | B18: НС-1291502 | C18: AS-18HW4SMATG015G | D18: =VLOOKUP($A18,'КРАТКИЙ ПРАЙС СПЛИТЫ'!$A:$M,2,0) -> AS-18HW4SMATG015 | F18: =VLOOKUP($A18,'КРАТКИЙ ПРАЙС СПЛИТЫ'!$A:$M,3,0) -> 5.3 | G18: =VLOOKUP($A18,'КРАТКИЙ ПРАЙС СПЛИТЫ'!$A:$M,4,0) -> 5.35 | H18: =VLOOKUP($A18,'КРАТКИЙ ПРАЙС СПЛИТЫ'!$A:$M,5,0) -> А/А | I18: =VLOOKUP($A18,'КРАТКИЙ ПРАЙС СПЛИТЫ'!$A:$M,6,0) -> 34,5/35/39/44/45 | J18: =VLOOKUP($A18,'КРАТКИЙ ПРАЙС СПЛИТЫ'!$A:$M,7,0) -> 1050x320x235 | K18: =VLOOKUP($A18,'КРАТКИЙ ПРАЙС СПЛИТЫ'!$A:$M,9,0) -> 12/38 | L18: =MROUND(O18*0.3,100) -> 19000 | M18: =MROUND(P18*0.3,100) -> 16100 | N18: =MROUND(Q18*0.3,100) -> 11600 | O18: =VLOOKUP($A18,'КРАТКИЙ ПРАЙС СПЛИТЫ'!$A:$M,10,0) -> 63490 | P18: =VLOOKUP($A18,'КРАТКИЙ ПРАЙС СПЛИТЫ'!$A:$M,11,0) -> 53790 | Q18: =VLOOKUP($A18,'КРАТКИЙ ПРАЙС СПЛИТЫ'!$A:$M,12,0) -> 38600 | R18: =Q18*(1-1*'Скидка '!D$5) -> 38600
B19: НС-1291504 | C19: AS-18HW4SMATG015W | F19: 2.1 | G19: 3.1 | H19: А/А | J19: =VLOOKUP($A18,'КРАТКИЙ ПРАЙС СПЛИТЫ'!$A:$M,8,0) -> 780×540×260 | K19: А/А | L19: =O18-L18 -> 44490 | M19: =P18-M18 -> 37690 | N19: =Q18-N18 -> 27000
A20: НС-1447647 | B20: НС-1291505 | C20: AS-24HW4SBATG005G | D20: =VLOOKUP($A20,'КРАТКИЙ ПРАЙС СПЛИТЫ'!$A:$M,2,0) -> AS-24HW4SBATG005 | F20: =VLOOKUP($A20,'КРАТКИЙ ПРАЙС СПЛИТЫ'!$A:$M,3,0) -> 7.2 | G20: =VLOOKUP($A20,'КРАТКИЙ ПРАЙС СПЛИТЫ'!$A:$M,4,0) -> 7.4 | H20: =VLOOKUP($A20,'КРАТКИЙ ПРАЙС СПЛИТЫ'!$A:$M,5,0) -> А/А | I20: =VLOOKUP($A20,'КРАТКИЙ ПРАЙС СПЛИТЫ'!$A:$M,6,0) -> 35/35,5/40/45,5/45,5 | J20: =VLOOKUP($A20,'КРАТКИЙ ПРАЙС СПЛИТЫ'!$A:$M,7,0) -> 1050x320x235 | K20: =VLOOKUP($A20,'КРАТКИЙ ПРАЙС СПЛИТЫ'!$A:$M,9,0) -> 14,5/45 | L20: =MROUND(O20*0.3,100) -> 24000 | M20: =MROUND(P20*0.3,100) -> 20400 | N20: =MROUND(Q20*0.3,100) -> 14800 | O20: =VLOOKUP($A20,'КРАТКИЙ ПРАЙС СПЛИТЫ'!$A:$M,10,0) -> 80090 | P20: =VLOOKUP($A20,'КРАТКИЙ ПРАЙС СПЛИТЫ'!$A:$M,11,0) -> 67890 | Q20: =VLOOKUP($A20,'КРАТКИЙ ПРАЙС СПЛИТЫ'!$A:$M,12,0) -> 49200 | R20: =Q20*(1-1*'Скидка '!D$5) -> 49200
B21: НС-1291506 | C21: AS-24HW4SBATG005W | F21: 2.1 | G21: 3.1 | H21: А/А | J21: =VLOOKUP($A20,'КРАТКИЙ ПРАЙС СПЛИТЫ'!$A:$M,8,0) -> 860x650x310 | K21: А/А | L21: =O20-L20 -> 56090 | M21: =P20-M20 -> 47490 | N21: =Q20-N20 -> 34400
C22: со встроенным Wi-Fi модулем
A23: НС-1691535 | B23: НС-1695554 | C23: AS-07HW4SYDTG035G | D23: =VLOOKUP($A23,'КРАТКИЙ ПРАЙС СПЛИТЫ'!$A:$M,2,0) -> AS-07HW4SYDTG035 WI-FI | F23: =VLOOKUP($A23,'КРАТКИЙ ПРАЙС СПЛИТЫ'!$A:$M,3,0) -> 2.1 | G23: =VLOOKUP($A23,'КРАТКИЙ ПРАЙС СПЛИТЫ'!$A:$M,4,0) -> 2.2 | H23: =VLOOKUP($A23,'КРАТКИЙ ПРАЙС СПЛИТЫ'!$A:$M,5,0) -> А/А | I23: =VLOOKUP($A23,'КРАТКИЙ ПРАЙС СПЛИТЫ'!$A:$M,6,0) -> 26/26,5/29/33/36 | J23: =VLOOKUP($A23,'КРАТКИЙ ПРАЙС СПЛИТЫ'!$A:$M,7,0) -> 880x275x207 | K23: =VLOOKUP($A23,'КРАТКИЙ ПРАЙС СПЛИТЫ'!$A:$M,9,0) -> 7/21,5 | L23: =O23-L24 -> 10100 | M23: =P23-M24 -> 8500 | N23: =Q23-N24 -> 6700 | O23: =VLOOKUP($A23,'КРАТКИЙ ПРАЙС СПЛИТЫ'!$A:$M,10,0) -> 29490 | P23: =VLOOKUP($A23,'КРАТКИЙ ПРАЙС СПЛИТЫ'!$A:$M,11,0) -> 24990 | Q23: =VLOOKUP($A23,'КРАТКИЙ ПРАЙС СПЛИТЫ'!$A:$M,12,0) -> 18500 | R23: =Q23*(1-1*'Скидка '!D$5) -> 18500
B24: НС-1291490 | C24: AS-07HW4SYDTG035W | F24: 2.1 | G24: 3.1 | H24: А/А | J24: =VLOOKUP($A23,'КРАТКИЙ ПРАЙС СПЛИТЫ'!$A:$M,8,0) -> 660x482x240 | K24: А/А | L24: =L13 -> 19390 | M24: =M13 -> 16490 | N24: =N13 -> 11800
A25: НС-1692478 | B25: НС-1691510 | C25: AS-10HW4SYDTG5G | D25: =VLOOKUP($A25,'КРАТКИЙ ПРАЙС СПЛИТЫ'!$A:$M,2,0) -> AS-10HW4SYDTG5 WI-FI | F25: =VLOOKUP($A25,'КРАТКИЙ ПРАЙС СПЛИТЫ'!$A:$M,3,0) -> 2.7 | G25: =VLOOKUP($A25,'КРАТКИЙ ПРАЙС СПЛИТЫ'!$A:$M,4,0) -> 2.75 | H25: =VLOOKUP($A25,'КРАТКИЙ ПРАЙС СПЛИТЫ'!$A:$M,5,0) -> А/А | I25: =VLOOKUP($A25,'КРАТКИЙ ПРАЙС СПЛИТЫ'!$A:$M,6,0) -> 31/31,5/34/37/37,5 | J25: =VLOOKUP($A25,'КРАТКИЙ ПРАЙС СПЛИТЫ'!$A:$M,7,0) -> 880x275x207 | K25: =VLOOKUP($A25,'КРАТКИЙ ПРАЙС СПЛИТЫ'!$A:$M,9,0) -> 8/24 | L25: =O25-L26 -> 10700 | M25: =P25-M26 -> 9100 | N25: =Q25-N26 -> 7100 | O25: =VLOOKUP($A25,'КРАТКИЙ ПРАЙС СПЛИТЫ'!$A:$M,10,0) -> 31790 | P25: =VLOOKUP($A25,'КРАТКИЙ ПРАЙС СПЛИТЫ'!$A:$M,11,0) -> 26990 | Q25: =VLOOKUP($A25,'КРАТКИЙ ПРАЙС СПЛИТЫ'!$A:$M,12,0) -> 20000 | R25: =Q25*(1-1*'Скидка '!D$5) -> 20000
B26: НС-1291492 | C26: AS-10HW4SYDTGW | F26: 2.1 | G26: 3.1 | H26: А/А | J26: =VLOOKUP($A25,'КРАТКИЙ ПРАЙС СПЛИТЫ'!$A:$M,8,0) -> 660x482x240 | K26: А/А | L26: =L15 -> 21090 | M26: =M15 -> 17890 | N26: =N15 -> 12900
A27: НС-1692479 | B27: НС-1691512 | C27: AS-13HW4SVDTG5G | D27: =VLOOKUP($A27,'КРАТКИЙ ПРАЙС СПЛИТЫ'!$A:$M,2,0) -> AS-13HW4SVDTG5 WI-FI | F27: =VLOOKUP($A27,'КРАТКИЙ ПРАЙС СПЛИТЫ'!$A:$M,3,0) -> 3.7 | G27: =VLOOKUP($A27,'КРАТКИЙ ПРАЙС СПЛИТЫ'!$A:$M,4,0) -> 3.75 | H27: =VLOOKUP($A27,'КРАТКИЙ ПРАЙС СПЛИТЫ'!$A:$M,5,0) -> А/А | I27: =VLOOKUP($A27,'КРАТКИЙ ПРАЙС СПЛИТЫ'!$A:$M,6,0) -> 32/32,5/34/36,5/37 | J27: =VLOOKUP($A27,'КРАТКИЙ ПРАЙС СПЛИТЫ'!$A:$M,7,0) -> 880x275x207 | K27: =VLOOKUP($A27,'КРАТКИЙ ПРАЙС СПЛИТЫ'!$A:$M,9,0) -> 8,4/27 | L27: =O27-L28 -> 14700 | M27: =P27-M28 -> 12500 | N27: =Q27-N28 -> 9600 | O27: =VLOOKUP($A27,'КРАТКИЙ ПРАЙС СПЛИТЫ'!$A:$M,10,0) -> 43590 | P27: =VLOOKUP($A27,'КРАТКИЙ ПРАЙС СПЛИТЫ'!$A:$M,11,0) -> 36990 | Q27: =VLOOKUP($A27,'КРАТКИЙ ПРАЙС СПЛИТЫ'!$A:$M,12,0) -> 27300 | R27: =Q27*(1-1*'Скидка '!D$5) -> 27300
B28: НС-1291501 | C28: AS-13HW4SVDTGW | F28: 2.1 | G28: 3.1 | H28: А/А | J28: =VLOOKUP($A27,'КРАТКИЙ ПРАЙС СПЛИТЫ'!$A:$M,8,0) -> 715x482x240 | K28: А/А | L28: =L17 -> 28890 | M28: =M17 -> 24490 | N28: =N17 -> 17700
A29: НС-1692481 | B29: НС-1691514 | C29: AS-18HW4SMATG015G | D29: =VLOOKUP($A29,'КРАТКИЙ ПРАЙС СПЛИТЫ'!$A:$M,2,0) -> AS-18HW4SMATG015 WI-FI | F29: =VLOOKUP($A29,'КРАТКИЙ ПРАЙС СПЛИТЫ'!$A:$M,3,0) -> 5.3 | G29: =VLOOKUP($A29,'КРАТКИЙ ПРАЙС СПЛИТЫ'!$A:$M,4,0) -> 5.35 | H29: =VLOOKUP($A29,'КРАТКИЙ ПРАЙС СПЛИТЫ'!$A:$M,5,0) -> А/А | I29: =VLOOKUP($A29,'КРАТКИЙ ПРАЙС СПЛИТЫ'!$A:$M,6,0) -> 34,5/35/39/44/45 | J29: =VLOOKUP($A29,'КРАТКИЙ ПРАЙС СПЛИТЫ'!$A:$M,7,0) -> 1050x320x235 | K29: =VLOOKUP($A29,'КРАТКИЙ ПРАЙС СПЛИТЫ'!$A:$M,9,0) -> 12/38 | L29: =O29-L30 -> 23700 | M29: =P29-M30 -> 20100 | N29: =Q29-N30 -> 15600 | O29: =VLOOKUP($A29,'КРАТКИЙ ПРАЙС СПЛИТЫ'!$A:$M,10,0) -> 68190 | P29: =VLOOKUP($A29,'КРАТКИЙ ПРАЙС СПЛИТЫ'!$A:$M,11,0) -> 57790 | Q29: =VLOOKUP($A29,'КРАТКИЙ ПРАЙС СПЛИТЫ'!$A:$M,12,0) -> 42600 | R29: =Q29*(1-1*'Скидка '!D$5) -> 42600
B30: НС-1291504 | C30: AS-18HW4SMATG015W | F30: 2.1 | G30: 3.1 | H30: А/А | J30: =VLOOKUP($A29,'КРАТКИЙ ПРАЙС СПЛИТЫ'!$A:$M,8,0) -> 780×540×260 | K30: А/А | L30: =L19 -> 44490 | M30: =M19 -> 37690 | N30: =N19 -> 27000
A31: НС-1692483 | B31: НС-1691517 | C31: AS-24HW4SBATG005G | D31: =VLOOKUP($A31,'КРАТКИЙ ПРАЙС СПЛИТЫ'!$A:$M,2,0) -> AS-24HW4SBATG005 WI-FI | F31: =VLOOKUP($A31,'КРАТКИЙ ПРАЙС СПЛИТЫ'!$A:$M,3,0) -> 7.2 | G31: =VLOOKUP($A31,'КРАТКИЙ ПРАЙС СПЛИТЫ'!$A:$M,4,0) -> 7.4 | H31: =VLOOKUP($A31,'КРАТКИЙ ПРАЙС СПЛИТЫ'!$A:$M,5,0) -> А/А | I31: =VLOOKUP($A31,'КРАТКИЙ ПРАЙС СПЛИТЫ'!$A:$M,6,0) -> 35/35,5/40/45,5/45,5 | J31: =VLOOKUP($A31,'КРАТКИЙ ПРАЙС СПЛИТЫ'!$A:$M,7,0) -> 1050x320x235 | K31: =VLOOKUP($A31,'КРАТКИЙ ПРАЙС СПЛИТЫ'!$A:$M,9,0) -> 14,5/45 | L31: =O31-L32 -> 29700 | M31: =P31-M32 -> 25200 | N31: =Q31-N32 -> 19600 | O31: =VLOOKUP($A31,'КРАТКИЙ ПРАЙС СПЛИТЫ'!$A:$M,10,0) -> 85790 | P31: =VLOOKUP($A31,'КРАТКИЙ ПРАЙС СПЛИТЫ'!$A:$M,11,0) -> 72690 | Q31: =VLOOKUP($A31,'КРАТКИЙ ПРАЙС СПЛИТЫ'!$A:$M,12,0) -> 54000 | R31: =Q31*(1-1*'Скидка '!D$5) -> 54000
B32: НС-1291506 | C32: AS-24HW4SBATG005W | F32: 2.1 | G32: 3.1 | H32: А/А | J32: =VLOOKUP($A31,'КРАТКИЙ ПРАЙС СПЛИТЫ'!$A:$M,8,0) -> 860x650x310 | K32: А/А | L32: =L21 -> 56090 | M32: =M21 -> 47490 | N32: =N21 -> 34400
C33: STRONG NEO Premium Classic A | Q33: УЗНАТЬ БОЛЬШЕ
G34: Высокая мощность 9,4 кВт | J34: ULTRA High Density фильтр
G35: Для больших помещений до 100 м² | J35: Функция Ifeel
G36: Удобная индикация режима работы | J36: Таймер на включение и отключение
G37: Современный стильный дизайн | J37: Отключение индикации внутреннего блока с пульта Dimmer
A39: НС-1276593 | B39: НС-1108071 | C39: AS-36HR4SDKVTG | D39: =VLOOKUP($A39,'КРАТКИЙ ПРАЙС СПЛИТЫ'!$A:$M,2,0) -> AS-36HR4SDKVT | F39: =VLOOKUP($A39,'КРАТКИЙ ПРАЙС СПЛИТЫ'!$A:$M,3,0) -> 9.4 | G39: =VLOOKUP($A39,'КРАТКИЙ ПРАЙС СПЛИТЫ'!$A:$M,4,0) -> 9.6 | H39: =VLOOKUP($A39,'КРАТКИЙ ПРАЙС СПЛИТЫ'!$A:$M,5,0) -> C/C | I39: =VLOOKUP($A39,'КРАТКИЙ ПРАЙС СПЛИТЫ'!$A:$M,6,0) -> 37/44/50 | J39: =VLOOKUP($A39,'КРАТКИЙ ПРАЙС СПЛИТЫ'!$A:$M,7,0) -> 1280×345×250 | K39: =VLOOKUP($A39,'КРАТКИЙ ПРАЙС СПЛИТЫ'!$A:$M,9,0) -> 19,5/60 | L39: =MROUND(O39*0.3,100) -> 42400 | M39: =MROUND(P39*0.3,100)-10 -> 35990 | N39: =MROUND(Q39*0.3,100) -> 26900 | O39: =VLOOKUP($A39,'КРАТКИЙ ПРАЙС СПЛИТЫ'!$A:$M,10,0) -> 141490 | P39: =VLOOKUP($A39,'КРАТКИЙ ПРАЙС СПЛИТЫ'!$A:$M,11,0) -> 119890 | Q39: =VLOOKUP($A39,'КРАТКИЙ ПРАЙС СПЛИТЫ'!$A:$M,12,0) -> 89600 | R39: =Q39*(1-1*'Скидка '!D$5) -> 89600
B40: НС-1108074 | C40: AS-36HR4SDKVTW | F40: 2.1 | G40: 3.1 | H40: А/А | J40: =VLOOKUP($A39,'КРАТКИЙ ПРАЙС СПЛИТЫ'!$A:$M,8,0) -> 885x795x366 | K40: А/А | L40: =O39-L39 -> 99090 | M40: =P39-M39 -> 83900 | N40: =Q39-N39 -> 62700
C41: STRONG VIBE Classic A NEW 2025 Wi-Fi | Q41: УЗНАТЬ БОЛЬШЕ
G42: Высокая мощность 10 кВт | J42: 4D-AUTO Air
...

Sheet RAC INVERTER+ПРИТОЧ. ВЕНТИЛЯЦИЯ
C2: ='КРАТКИЙ ПРАЙС СПЛИТЫ'!B2 -> ПРАЙС-ЛИСТ ДЕЙСТВИТЕЛЕН С 01.01.2026
A3: НС-комплекта | B3: Код блока | C3: Артикул | D3: Модель | E3: Мощность, кВт | G3: Класс энергоэф- фективности | H3: Уров. Шума внутреннего блока ДБ(A) | I3: Габариты блока (ШхВхГ), мм | J3: Вес нетто, внутр/наруж., кг | K3: РРЦ, руб | L3: РИЦ, руб | M3: Дилерская цена, руб. | N3: РРЦ, руб | O3: РИЦ, руб | P3: Дилерская цена, руб. | Q3: Ваша Спец цена, руб
E4: охл. | F4: нагр. | I4: Нетто | K4: Блок | L4: Блок | M4: Блок | P4: Комплект | Q4: Комплект
C6: AIR SENSATION Superior DC Inverter | P6: УЗНАТЬ БОЛЬШЕ
F7: Класс эффективности A+++/A+++ | I7: Озонобезопасный хладагент R32 | P7: СМОТРЕТЬ ВИДЕО
F8: Приток свежего воздуха до 50м3/час | I8: Работа на обогрев при температуре до -20 °С
F9: Датчик CO2 с индикацией качества воздуха | I9: Фильтр HEPA класса H11 на приточный воздух
F10: Wi-Fi управление (стандартно) | I10: Датчик влажности
F11: Интеллектуальный режим Assistant Intelligent | I11: Подключение к BACnet/Modbus/центральное управление (опция)
F12: Hi-Nano-генератор ионов (до 1млн ионов/см3) | I12: РАБОТАЕТ с ЯНДЕКС. АЛИСА
A15: НС-1413600 | B15: НС-1403590 | C15: AS-10UW4RXVQF00G | D15: =VLOOKUP($A15,'КРАТКИЙ ПРАЙС СПЛИТЫ'!$A:$M,2,0) -> AS-10UW4RXVQF00 | E15: =VLOOKUP($A15,'КРАТКИЙ ПРАЙС СПЛИТЫ'!$A:$M,3,0) -> 2,6(1,0-4,0) | F15: =VLOOKUP($A15,'КРАТКИЙ ПРАЙС СПЛИТЫ'!$A:$M,4,0) -> 3,2(1,6-4,2) | G15: =VLOOKUP($A15,'КРАТКИЙ ПРАЙС СПЛИТЫ'!$A:$M,5,0) -> A+++/A+++ | H15: =VLOOKUP($A15,'КРАТКИЙ ПРАЙС СПЛИТЫ'!$A:$M,6,0) -> 18/25/28/31/33/35/37 | I15: =VLOOKUP($A15,'КРАТКИЙ ПРАЙС СПЛИТЫ'!$A:$M,7,0) -> 978×313×217 | J15: =VLOOKUP($A15,'КРАТКИЙ ПРАЙС СПЛИТЫ'!$A:$M,9,0) -> 13,5/33 | K15: =MROUND(N15*0.3,100) -> 24300 | L15: =MROUND(O15*0.3,100) -> 20600 | M15: =MROUND(P15*0.3,100) -> 15400 | N15: =VLOOKUP($A15,'КРАТКИЙ ПРАЙС СПЛИТЫ'!$A:$M,10,0) -> 80990 | O15: =VLOOKUP($A15,'КРАТКИЙ ПРАЙС СПЛИТЫ'!$A:$M,11,0) -> 68690 | P15: =VLOOKUP($A15,'КРАТКИЙ ПРАЙС СПЛИТЫ'!$A:$M,12,0) -> 51200 | Q15: =P15*(1-1*'Скидка '!D$4) -> 51200
B16: НС-1403595 | C16: AS-10UW4RXVQF00W | E16: 2.1 | F16: 3.1 | G16: А/А | I16: =VLOOKUP($A15,'КРАТКИЙ ПРАЙС СПЛИТЫ'!$A:$M,8,0) -> 810×585×280 | J16: А/А | K16: =N15-K15 -> 56690 | L16: =O15-L15 -> 48090 | M16: =P15-M15 -> 35800
A17: НС-1413603 | B17: НС-1403597 | C17: AS-13UW4RXVQF00G | D17: =VLOOKUP($A17,'КРАТКИЙ ПРАЙС СПЛИТЫ'!$A:$M,2,0) -> AS-13UW4RXVQF00 | E17: =VLOOKUP($A17,'КРАТКИЙ ПРАЙС СПЛИТЫ'!$A:$M,3,0) -> 3,5(1,0-4,4) | F17: =VLOOKUP($A17,'КРАТКИЙ ПРАЙС СПЛИТЫ'!$A:$M,4,0) -> 4,2(1,6-4,8) | G17: =VLOOKUP($A17,'КРАТКИЙ ПРАЙС СПЛИТЫ'!$A:$M,5,0) -> A+++/A+++ | H17: =VLOOKUP($A17,'КРАТКИЙ ПРАЙС СПЛИТЫ'!$A:$M,6,0) -> 18/25/28,5/31/33,5/35,5/38 | I17: =VLOOKUP($A17,'КРАТКИЙ ПРАЙС СПЛИТЫ'!$A:$M,7,0) -> 978×313×217 | J17: =VLOOKUP($A17,'КРАТКИЙ ПРАЙС СПЛИТЫ'!$A:$M,9,0) -> 13,5/33 | K17: =MROUND(N17*0.3,100) -> 26700 | L17: =MROUND(O17*0.3,100) -> 22600 | M17: =MROUND(P17*0.3,100) -> 16900 | N17: =VLOOKUP($A17,'КРАТКИЙ ПРАЙС СПЛИТЫ'!$A:$M,10,0) -> 88990 | O17: =VLOOKUP($A17,'КРАТКИЙ ПРАЙС СПЛИТЫ'!$A:$M,11,0) -> 75490 | P17: =VLOOKUP($A17,'КРАТКИЙ ПРАЙС СПЛИТЫ'!$A:$M,12,0) -> 56200 | Q17: =P17*(1-1*'Скидка '!D$4) -> 56200
B18: НС-1403598 | C18: AS-13UW4RXVQF00W | E18: 2.1 | F18: 3.1 | G18: А/А | I18: =VLOOKUP($A17,'КРАТКИЙ ПРАЙС СПЛИТЫ'!$A:$M,8,0) -> 810×585×280 | J18: А/А | K18: =N17-K17 -> 62290 | L18: =O17-L17 -> 52890 | M18: =P17-M17 -> 39300
B20: Код | C20: Артикул | D20: Фото | E20: Описание | K20: РРЦ, руб | L20: РИЦ, руб | M20: Дилерская цена, руб. | N20: РРЦ, руб | O20: РИЦ, руб | P20: Дилерская цена, руб. | Q20: Ваша Спец цена, руб
A21: НС-1494331 | B21: НС-1494331 | C21: YXE-E01U(E) | E21: Индивидуальный проводной пульт. Поставляется в комплекте к канальным блокам. Опция – для кассетных, напольно-потолочных и колонных блоков (48/60k) Высококонтрастный дисплей, сенсорные кнопки, Возможность настройки давления для канальных блоков с точностью 1Па, Раздельное управление жалюзи кассетных блоков (мульти сплит-системы), Встроенный ИК-приемник | K21: =N21 -> 11760 | L21: =O21 -> 10069.5 | M21: =P21 -> 6900 | N21: =VLOOKUP($A21,'КРАТКИЙ ПРАЙС СПЛИТЫ'!$A:$M,10,0) -> 11760 | O21: =VLOOKUP($A21,'КРАТКИЙ ПРАЙС СПЛИТЫ'!$A:$M,11,0) -> 10069.5 | P21: =VLOOKUP($A21,'КРАТКИЙ ПРАЙС СПЛИТЫ'!$A:$M,12,0) -> 6900 | Q21: =P21*(1-1*'Скидка '!D$7) -> 6900
A22: НС-1096207 | B22: НС-1096207 | C22: YJE-C01T(E) | E22: Центральный контроллер позволяет задавать как индивидуальные параметры работы для каждого кондиционера, так и общие для всей системы. Позволяет централизованно управлять системой до 16 внутренних блоков (необходим адаптер B544 (E) на каждый внутренний блок) | K22: =N22 -> 22890 | L22: =O22 -> 19624.5 | M22: =P22 -> 13300 | N22: =VLOOKUP($A22,'КРАТКИЙ ПРАЙС СПЛИТЫ'!$A:$M,10,0) -> 22890 | O22: =VLOOKUP($A22,'КРАТКИЙ ПРАЙС СПЛИТЫ'!$A:$M,11,0) -> 19624.5 | P22: =VLOOKUP($A22,'КРАТКИЙ ПРАЙС СПЛИТЫ'!$A:$M,12,0) -> 13300 | Q22: =P22*(1-1*'Скидка '!D$7) -> 13300
A23: НС-1492600 | B23: НС-1492600 | C23: Адаптер преобразования сигнала B544(E) | E23: Для всех блоков, у которых есть разъем для проводного пульта. Предназначен для подключения сплит-систем Hisense к системам центрального управления и диспетчеризации. • Обеспечивает подключение к центральному пульту YJE-C01T(E) (до 16 блоков) • Обеспечивает подключение к системам диспетчеризации BACnet / Modbus (до 255 блоков) | K23: =N23 -> 8400 | L23: =O23 -> 7234.5 | M23: =P23 -> 4900 | N23: =VLOOKUP($A23,'КРАТКИЙ ПРАЙС СПЛИТЫ'!$A:$M,10,0) -> 8400 | O23: =VLOOKUP($A23,'КРАТКИЙ ПРАЙС СПЛИТЫ'!$A:$M,11,0) -> 7234.5 | P23: =VLOOKUP($A23,'КРАТКИЙ ПРАЙС СПЛИТЫ'!$A:$M,12,0) -> 4900 | Q23: =P23*(1-1*'Скидка '!D$7) -> 4900
A24: НС-1423878 | B24: НС-1423878 | C24: HEPA-фильтр для кондиционеров AIR SENSATION | F24: HEPA-фильтр для кондиционеров AIR SENSATION | K24: =N24 -> 2690 | L24: =O24 -> 2290 | M24: =P24 -> 1500 | N24: 2690 | O24: 2290 | P24: 1500 | Q24: =P24*(1-1*'Скидка '!D$7) -> 1500

Sheet RAC INVERTER
C2: ='КРАТКИЙ ПРАЙС СПЛИТЫ'!B2 -> ПРАЙС-ЛИСТ ДЕЙСТВИТЕЛЕН С 01.01.2026
A3: НС-комплекта | B3: Код блока | C3: Артикул | D3: Модель | E3: РЕКОМЕНДОВАННО ДЛЯ ПРОДАЖИ НА МП | F3: Мощность, кВт | H3: Класс энергоэф- фективности | I3: Уров. Шума внутреннего блока ДБ(A) | J3: Габариты блока (ШхВхГ), мм | K3: Вес нетто, внутр/наруж., кг | L3: РРЦ, руб | M3: РИЦ, руб | N3: Дилерская цена, руб. | O3: РРЦ, руб | P3: РИЦ, руб | Q3: Дилерская цена, руб. | R3: Ваша Спец цена, руб
F4: охл. | G4: нагр. | J4: Нетто | L4: Блок | M4: Блок | N4: Блок | Q4: Комплект | R4: Комплект
C5: VISION PRO SUPERIOR DC Inverter | G5: Класс эффективности A+++/A+++ | J5: FULL ICE CLEAN Очистка всех теплообменников | Q5: УЗНАТЬ БОЛЬШЕ
G6: Wi-Fi управление (стандартно) | J6: От 18 дБ(А) Низкий уровень шума | Q6: СМОТРЕТЬ ВИДЕО
G7: Интеллектуальный режим Assistant Intelligent | J7: Работа на обогрев до -25°C
G8: Hi-Nano-генератор ионов (до 1млн ионов/см3) | J8: FULL 3 DC Inverter, ЭРВ
G9: SMART EYE | J9: 4 режима сна
G10: РАБОТАЕТ с ЯНДЕКС. АЛИСА | J10: Подключение к BACnet/Modbus/центральное управление (опция)
C11: распродажа остатков сезона 2025
A12: НС-1601145 | B12: НС-1601118 | C12: AS-10UW4RXVQH00AG | D12: =VLOOKUP($A12,'КРАТКИЙ ПРАЙС СПЛИТЫ'!$A:$M,2,0) -> AS-10UW4RXVQH00A | F12: =VLOOKUP($A12,'КРАТКИЙ ПРАЙС СПЛИТЫ'!$A:$M,3,0) -> 2,60 (1,00-4,00) | G12: =VLOOKUP($A12,'КРАТКИЙ ПРАЙС СПЛИТЫ'!$A:$M,4,0) -> 3,20 (1,60-4,20) | H12: =VLOOKUP($A12,'КРАТКИЙ ПРАЙС СПЛИТЫ'!$A:$M,5,0) -> A+++/A+++ | I12: =VLOOKUP($A12,'КРАТКИЙ ПРАЙС СПЛИТЫ'!$A:$M,6,0) -> 18/20/22/27/30/31/33 | J12: =VLOOKUP($A12,'КРАТКИЙ ПРАЙС СПЛИТЫ'!$A:$M,7,0) -> 877×301×194 | K12: =VLOOKUP($A12,'КРАТКИЙ ПРАЙС СПЛИТЫ'!$A:$M,9,0) -> 10/33 | L12: =MROUND(O12*0.3,100) -> 26500 | M12: =MROUND(P12*0.3,100) -> 22400 | N12: =MROUND(Q12*0.3,100) -> 16900 | O12: =VLOOKUP($A12,'КРАТКИЙ ПРАЙС СПЛИТЫ'!$A:$M,10,0) -> 88490 | P12: =VLOOKUP($A12,'КРАТКИЙ ПРАЙС СПЛИТЫ'!$A:$M,11,0) -> 74790 | Q12: =VLOOKUP($A12,'КРАТКИЙ ПРАЙС СПЛИТЫ'!$A:$M,12,0) -> 56400 | R12: =Q12*(1-1*'Скидка '!D$4) -> 56400
B13: НС-1601119 | C13: AS-10UW4RXVQH00AW | F13: 2.1 | G13: 3.1 | H13: А/А | J13: =VLOOKUP($A12,'КРАТКИЙ ПРАЙС СПЛИТЫ'!$A:$M,8,0) -> 810×585×280 | K13: А/А | L13: =O12-L12 -> 61990 | M13: =P12-M12 -> 52390 | N13: =Q12-N12 -> 39500
A14: НС-1601147 | B14: НС-1601120 | C14: AS-13UW4RXVQH01G | D14: =VLOOKUP($A14,'КРАТКИЙ ПРАЙС СПЛИТЫ'!$A:$M,2,0) -> AS-13UW4RXVQH01 | F14: =VLOOKUP($A14,'КРАТКИЙ ПРАЙС СПЛИТЫ'!$A:$M,3,0) -> 3,50 (1,00-4,40) | G14: =VLOOKUP($A14,'КРАТКИЙ ПРАЙС СПЛИТЫ'!$A:$M,4,0) -> 4,20 (1,60-4,80) | H14: =VLOOKUP($A14,'КРАТКИЙ ПРАЙС СПЛИТЫ'!$A:$M,5,0) -> A+++/A+++ | I14: =VLOOKUP($A14,'КРАТКИЙ ПРАЙС СПЛИТЫ'!$A:$M,6,0) -> 18/20/22/27/30/31/33 | J14: =VLOOKUP($A14,'КРАТКИЙ ПРАЙС СПЛИТЫ'!$A:$M,7,0) -> 877×301×194 | K14: =VLOOKUP($A14,'КРАТКИЙ ПРАЙС СПЛИТЫ'!$A:$M,9,0) -> 10/33 | L14: =MROUND(O14*0.3,100) -> 28300 | M14: =MROUND(P14*0.3,100) -> 24000 | N14: =MROUND(Q14*0.3,100) -> 18100 | O14: =VLOOKUP($A14,'КРАТКИЙ ПРАЙС СПЛИТЫ'!$A:$M,10,0) -> 94490 | P14: =VLOOKUP($A14,'КРАТКИЙ ПРАЙС СПЛИТЫ'!$A:$M,11,0) -> 79990 | Q14: =VLOOKUP($A14,'КРАТКИЙ ПРАЙС СПЛИТЫ'!$A:$M,12,0) -> 60200 | R14: =Q14*(1-1*'Скидка '!D$4) -> 60200
B15: НС-1601121 | C15: AS-13UW4RXVQH01W | F15: 2.1 | G15: 3.1 | H15: А/А | J15: =VLOOKUP($A14,'КРАТКИЙ ПРАЙС СПЛИТЫ'!$A:$M,8,0) -> 810×585×280 | K15: А/А | L15: =O14-L14 -> 66190 | M15: =P14-M14 -> 55990 | N15: =Q14-N14 -> 42100
A16: НС-1716163 | B16: НС-1716161 | C16: AS-18UW4RBVQH00G | D16: =VLOOKUP($A16,'КРАТКИЙ ПРАЙС СПЛИТЫ'!$A:$M,2,0) -> AS-18UW4RBVQH00 | F16: =VLOOKUP($A16,'КРАТКИЙ ПРАЙС СПЛИТЫ'!$A:$M,3,0) -> 5,00 (1,50-6,00) | G16: =VLOOKUP($A16,'КРАТКИЙ ПРАЙС СПЛИТЫ'!$A:$M,4,0) -> 5,20 (1,60-6,20) | H16: =VLOOKUP($A16,'КРАТКИЙ ПРАЙС СПЛИТЫ'!$A:$M,5,0) -> A++/A+++ | I16: =VLOOKUP($A16,'КРАТКИЙ ПРАЙС СПЛИТЫ'!$A:$M,6,0) -> 29/32/35/38/40/42/45 | J16: =VLOOKUP($A16,'КРАТКИЙ ПРАЙС СПЛИТЫ'!$A:$M,7,0) -> 877×301×194 | K16: =VLOOKUP($A16,'КРАТКИЙ ПРАЙС СПЛИТЫ'!$A:$M,9,0) -> 10/39 | L16: =MROUND(O16*0.3,100) -> 42900 | M16: =MROUND(P16*0.3,100) -> 36400 | N16: =MROUND(Q16*0.3,100) -> 27500 | O16: =VLOOKUP($A16,'КРАТКИЙ ПРАЙС СПЛИТЫ'!$A:$M,10,0) -> 142990 | P16: =VLOOKUP($A16,'КРАТКИЙ ПРАЙС СПЛИТЫ'!$A:$M,11,0) -> 121390 | Q16: =VLOOKUP($A16,'КРАТКИЙ ПРАЙС СПЛИТЫ'!$A:$M,12,0) -> 91500 | R16: =Q16*(1-1*'Скидка '!D$4) -> 91500
B17: НС-1716162 | C17: AS-18UW4RBVQH00W | F17: 2.1 | G17: 3.1 | H17: А/А | J17: =VLOOKUP($A16,'КРАТКИЙ ПРАЙС СПЛИТЫ'!$A:$M,8,0) -> 860×667×310 | K17: А/А | L17: =O16-L16 -> 100090 | M17: =P16-M16 -> 84990 | N17: =Q16-N16 -> 64000
C18: VISION PRO CARBON SUPERIOR DC Inverter | G18: Класс эффективности A+++/A+++ | J18: FULL ICE CLEAN Очистка всех теплообменников | Q18: УЗНАТЬ БОЛЬШЕ
G19: Wi-Fi управление (стандартно) | J19: От 18 дБ(А) Низкий уровень шума | Q19: СМОТРЕТЬ ВИДЕО
G20: Интеллектуальный режим Assistant Intelligent | J20: Работа на обогрев до -25°C
G21: Hi-Nano-генератор ионов (до 1млн ионов/см3) | J21: FULL 3 DC Inverter, ЭРВ
G22: SMART EYE | J22: 4 режима сна
G23: РАБОТАЕТ с ЯНДЕКС. АЛИСА | J23: Подключение к BACnet/Modbus/центральное управление (опция)
A24: НС-1601149 | B24: НС-1601122 | C24: AS-10UW4RXVQH00AG(B) | D24: =VLOOKUP($A24,'КРАТКИЙ ПРАЙС СПЛИТЫ'!$A:$M,2,0) -> AS-10UW4RXVQH00A(B) | F24: =VLOOKUP($A24,'КРАТКИЙ ПРАЙС СПЛИТЫ'!$A:$M,3,0) -> 2,60 (1,00-4,00) | G24: =VLOOKUP($A24,'КРАТКИЙ ПРАЙС СПЛИТЫ'!$A:$M,4,0) -> 3,20 (1,60-4,20) | H24: =VLOOKUP($A24,'КРАТКИЙ ПРАЙС СПЛИТЫ'!$A:$M,5,0) -> A+++/A+++ | I24: =VLOOKUP($A24,'КРАТКИЙ ПРАЙС СПЛИТЫ'!$A:$M,6,0) -> 18/20/22/27/30/31/33 | J24: =VLOOKUP($A24,'КРАТКИЙ ПРАЙС СПЛИТЫ'!$A:$M,7,0) -> 883×305×198 | K24: =VLOOKUP($A24,'КРАТКИЙ ПРАЙС СПЛИТЫ'!$A:$M,9,0) -> 10/33 | L24: =MROUND(O24*0.3,100) -> 30900 | M24: =MROUND(P24*0.3,100) -> 26200 | N24: =MROUND(Q24*0.3,100) -> 19700 | O24: =VLOOKUP($A24,'КРАТКИЙ ПРАЙС СПЛИТЫ'!$A:$M,10,0) -> 102990 | P24: =VLOOKUP($A24,'КРАТКИЙ ПРАЙС СПЛИТЫ'!$A:$M,11,0) -> 87390 | Q24: =VLOOKUP($A24,'КРАТКИЙ ПРАЙС СПЛИТЫ'!$A:$M,12,0) -> 65800 | R24: =Q24*(1-1*'Скидка '!D$4) -> 65800
B25: НС-1601125 | C25: AS-10UW4RXVQH00AW(B) | F25: 2.1 | G25: 3.1 | H25: А/А | J25: =VLOOKUP($A24,'КРАТКИЙ ПРАЙС СПЛИТЫ'!$A:$M,8,0) -> 810×585×280 | K25: А/А | L25: =O24-L24 -> 72090 | M25: =P24-M24 -> 61190 | N25: =Q24-N24 -> 46100
A26: НС-1601150 | B26: НС-1601127 | C26: AS-13UW4RXVQH01G(B) | D26: =VLOOKUP($A26,'КРАТКИЙ ПРАЙС СПЛИТЫ'!$A:$M,2,0) -> AS-13UW4RXVQH01(B) | F26: =VLOOKUP($A26,'КРАТКИЙ ПРАЙС СПЛИТЫ'!$A:$M,3,0) -> 3,50 (1,00-4,40) | G26: =VLOOKUP($A26,'КРАТКИЙ ПРАЙС СПЛИТЫ'!$A:$M,4,0) -> 4,20 (1,60-4,80) | H26: =VLOOKUP($A26,'КРАТКИЙ ПРАЙС СПЛИТЫ'!$A:$M,5,0) -> A+++/A+++ | I26: =VLOOKUP($A26,'КРАТКИЙ ПРАЙС СПЛИТЫ'!$A:$M,6,0) -> 18/20/22/27/30/31/33 | J26: =VLOOKUP($A26,'КРАТКИЙ ПРАЙС СПЛИТЫ'!$A:$M,7,0) -> 883×305×198 | K26: =VLOOKUP($A26,'КРАТКИЙ ПРАЙС СПЛИТЫ'!$A:$M,9,0) -> 10/33 | L26: =MROUND(O26*0.3,100) -> 33400 | M26: =MROUND(P26*0.3,100) -> 28400 | N26: =MROUND(Q26*0.3,100) -> 21400 | O26: =VLOOKUP($A26,'КРАТКИЙ ПРАЙС СПЛИТЫ'!$A:$M,10,0) -> 111490 | P26: =VLOOKUP($A26,'КРАТКИЙ ПРАЙС СПЛИТЫ'!$A:$M,11,0) -> 94590 | Q26: =VLOOKUP($A26,'КРАТКИЙ ПРАЙС СПЛИТЫ'!$A:$M,12,0) -> 71200 | R26: =Q26*(1-1*'Скидка '!D$4) -> 71200
B27: НС-1601128 | C27: AS-13UW4RXVQH01W(B) | F27: 2.1 | G27: 3.1 | H27: А/А | J27: =VLOOKUP($A26,'КРАТКИЙ ПРАЙС СПЛИТЫ'!$A:$M,8,0) -> 810×585×280 | K27: А/А | L27: =O26-L26 -> 78090 | M27: =P26-M26 -> 66190 | N27: =Q26-N26 -> 49800
C28: PREMIUM Design Super DC Inverter 2025 WI-FI | Q28: УЗНАТЬ БОЛЬШЕ
G29: Класс эффективности A++/A+ | J29: Silver ion*, фотокаталитический фильтр* | Q29: СМОТРЕТЬ ВИДЕО
G30: Функция Ice Clean (внутренний блок) | J30: 4D AUTO AIR
G31: Wi-Fi управление (встроенный модуль) | J31: Работа на обогрев до -17°C
G32: Cold Plasma Ion Generator | J32: Низкий уровень шума от 22 дб(А)
G33: 7 скоростей вентилятора | J33: Подключение к BACnet/Modbus/центральное управление (опция) | Q33: *только модели 10k, 13k
C34: распродажа остатков без встроенного Wi-Fi
A35: НС-1497190 | B35: НС-1447270 | C35: AS-10UW4RVETG01G | D35: =VLOOKUP($A35,'КРАТКИЙ ПРАЙС СПЛИТЫ'!$A:$M,2,0) -> AS-10UW4RVETG01 | F35: =VLOOKUP($A35,'КРАТКИЙ ПРАЙС СПЛИТЫ'!$A:$M,3,0) -> 2,6(0,8-3,5) | G35: =VLOOKUP($A35,'КРАТКИЙ ПРАЙС СПЛИТЫ'!$A:$M,4,0) -> 2,8(0,8-3,5) | H35: =VLOOKUP($A35,'КРАТКИЙ ПРАЙС СПЛИТЫ'!$A:$M,5,0) -> А++/А+ | I35: =VLOOKUP($A35,'КРАТКИЙ ПРАЙС СПЛИТЫ'!$A:$M,6,0) -> 22/27,5/29/30,5/32,5/35,5/38 | J35: =VLOOKUP($A35,'КРАТКИЙ ПРАЙС СПЛИТЫ'!$A:$M,7,0) -> 950x272x207 | K35: =VLOOKUP($A35,'КРАТКИЙ ПРАЙС СПЛИТЫ'!$A:$M,9,0) -> 9/24 | L35: =MROUND(O35*0.3,100) -> 14700 | M35: =MROUND(P35*0.3,100) -> 12500 | N35: =MROUND(Q35*0.3,100) -> 9100 | O35: =VLOOKUP($A35,'КРАТКИЙ ПРАЙС СПЛИТЫ'!$A:$M,10,0) -> 49090 | P35: =VLOOKUP($A35,'КРАТКИЙ ПРАЙС СПЛИТЫ'!$A:$M,11,0) -> 41590 | Q35: =VLOOKUP($A35,'КРАТКИЙ ПРАЙС СПЛИТЫ'!$A:$M,12,0) -> 30200 | R35: =Q35*(1-1*'Скидка '!D$4) -> 30200
B36: НС-1447271 | C36: AS-10UW4RVETG01W | F36: 2.1 | G36: 3.1 | H36: А/А | J36: =VLOOKUP($A35,'КРАТКИЙ ПРАЙС СПЛИТЫ'!$A:$M,8,0) -> 715x482x240 | K36: А/А | L36: =O35-L35 -> 34390 | M36: =P35-M35 -> 29090 | N36: =Q35-N35 -> 21100
A37: НС-1497191 | B37: НС-1447272 | C37: AS-13UW4RVETG01G | D37: =VLOOKUP($A37,'КРАТКИЙ ПРАЙС СПЛИТЫ'!$A:$M,2,0) -> AS-13UW4RVETG01 | F37: =VLOOKUP($A37,'КРАТКИЙ ПРАЙС СПЛИТЫ'!$A:$M,3,0) -> 3,5(1,2-4,1) | G37: =VLOOKUP($A37,'КРАТКИЙ ПРАЙС СПЛИТЫ'!$A:$M,4,0) -> 4,0(1,6-4,3) | H37: =VLOOKUP($A37,'КРАТКИЙ ПРАЙС СПЛИТЫ'!$A:$M,5,0) -> А++/А+ | I37: =VLOOKUP($A37,'КРАТКИЙ ПРАЙС СПЛИТЫ'!$A:$M,6,0) -> 23/27,5/29/32/34/36,5/40,5 | J37: =VLOOKUP($A37,'КРАТКИЙ ПРАЙС СПЛИТЫ'!$A:$M,7,0) -> 950x272x207 | K37: =VLOOKUP($A37,'КРАТКИЙ ПРАЙС СПЛИТЫ'!$A:$M,9,0) -> 9/25 | L37: =MROUND(O37*0.3,100) -> 16600 | M37: =MROUND(P37*0.3,100) -> 14100 | N37: =MROUND(Q37*0.3,100) -> 10300 | O37: =VLOOKUP($A37,'КРАТКИЙ ПРАЙС СПЛИТЫ'!$A:$M,10,0) -> 55390 | P37: =VLOOKUP($A37,'КРАТКИЙ ПРАЙС СПЛИТЫ'!$A:$M,11,0) -> 46990 | Q37: =VLOOKUP($A37,'КРАТКИЙ ПРАЙС СПЛИТЫ'!$A:$M,12,0) -> 34200 | R37: =Q37*(1-1*'Скидка '!D$4) -> 34200
B38: НС-1447274 | C38: AS-13UW4RVETG01W | F38: 2.1 | G38: 3.1 | H38: А/А | J38: =VLOOKUP($A37,'КРАТКИЙ ПРАЙС СПЛИТЫ'!$A:$M,8,0) -> 715x482x240 | K38: А/А | L38: =O37-L37 -> 38790 | M38: =P37-M37 -> 32890 | N38: =Q37-N37 -> 23900
A39: НС-1497192 | B39: НС-1447277 | C39: AS-18UW4RXATG03G | D39: =VLOOKUP($A39,'КРАТКИЙ ПРАЙС СПЛИТЫ'!$A:$M,2,0) -> AS-18UW4RXATG03 | F39: =VLOOKUP($A39,'КРАТКИЙ ПРАЙС СПЛИТЫ'!$A:$M,3,0) -> 5,0(1,0-6,0) | G39: =VLOOKUP($A39,'КРАТКИЙ ПРАЙС СПЛИТЫ'!$A:$M,4,0) -> 5,6(1,6-6,25) | H39: =VLOOKUP($A39,'КРАТКИЙ ПРАЙС СПЛИТЫ'!$A:$M,5,0) -> А++/А+ | I39: =VLOOKUP($A39,'КРАТКИЙ ПРАЙС СПЛИТЫ'!$A:$M,6,0) -> 29/33,5/36/38/40/42,5/43,5 | J39: =VLOOKUP($A39,'КРАТКИЙ ПРАЙС СПЛИТЫ'!$A:$M,7,0) -> 1050x320x235 | K39: =VLOOKUP($A39,'КРАТКИЙ ПРАЙС СПЛИТЫ'!$A:$M,9,0) -> 12/33 | L39: =MROUND(O39*0.3,100) -> 27200 | M39: =MROUND(P39*0.3,100) -> 23100 | N39: =MROUND(Q39*0.3,100) -> 16900 | O39: =VLOOKUP($A39,'КРАТКИЙ ПРАЙС СПЛИТЫ'!$A:$M,10,0) -> 90690 | P39: =VLOOKUP($A39,'КРАТКИЙ ПРАЙС СПЛИТЫ'!$A:$M,11,0) -> 76890 | Q39: =VLOOKUP($A39,'КРАТКИЙ ПРАЙС СПЛИТЫ'!$A:$M,12,0) -> 56200 | R39: =Q39*(1-1*'Скидка '!D$4) -> 56200
B40: НС-1447278 | C40: AS-18UW4RXATG03W | F40: 2.1 | G40: 3.1 | H40: А/А | J40: =VLOOKUP($A39,'КРАТКИЙ ПРАЙС СПЛИТЫ'!$A:$M,8,0) -> 810x585x280 | K40: А/А | L40: =O39-L39 -> 63490 | M40: =P39-M39 -> 53790 | N40: =Q39-N39 -> 39300
C41: со встроенным Wi-Fi модулем
...

Sheet LCAC ON-OFF
C2: ='КРАТКИЙ ПРАЙС СПЛИТЫ'!B2 -> ПРАЙС-ЛИСТ ДЕЙСТВИТЕЛЕН С 01.01.2026
A3: НС-комплекта | B3: Кодблока | C3: Артикул | D3: Модель | E3: Мощность, кВт | G3: Класс энергоэф- фективности | H3: Уров. Шума внутреннего блока ДБ(A) | I3: Габариты блока (ДхВхГ), мм | K3: Вес нетто, кг | L3: РРЦ, руб | M3: РИЦ, руб | N3: Дилерская цена, руб. | O3: РРЦ, руб | P3: РИЦ, руб | Q3: Дилерская цена, руб. | R3: Ваша Спец цена, руб
E4: охл. | F4: нагр. | I4: Внутренний | J4: Наружный | L4: Блок | M4: Блок | N4: Блок | Q4: Комплект | R4: Комплект
C5: СПЛИТ-СИСТЕМЫ КОЛОННОГО ТИПА HEAVY CLASSIC
F6: Энергоэффективность класса A/B | I6: Функция Самоочистки
F7: Монолитная конструкция | I7: Дополнительный нагреватель в режиме работы на обогрев
F8: LED дисплей с Touch screen (Тач скрин) | I8: Элегантный дизайн внутреннего блока
F9: 4D AUTO-Air | I9: Низкий уровень шума
F10: Запатентованная воздухозаборная решетка | I10: Диапазон работы на охлаждение/обогрев -15°С/-10°С
F11: Дополнительный нагреватель в режиме работы на обогрев | I11: Долговечный и легкосъемный фильтр воздуха
I12: *Кроме 24k
A13: НС-1349686 | B13: НС-1291732 | C13: =LEFT(D13,FIND("/",D13,1)-1) -> AUF-24ER4SCPA | D13: =VLOOKUP($A13,'КРАТКИЙ ПРАЙС СПЛИТЫ'!$A:$M,2,0) -> AUF-24ER4SCPA/AUW-24H4SB | E13: =VLOOKUP($A13,'КРАТКИЙ ПРАЙС СПЛИТЫ'!$A:$M,3,0) -> 7.2 | F13: =VLOOKUP($A13,'КРАТКИЙ ПРАЙС СПЛИТЫ'!$A:$M,4,0) -> 8,12 + 2,5 | G13: =VLOOKUP($A13,'КРАТКИЙ ПРАЙС СПЛИТЫ'!$A:$M,5,0) -> А/A | H13: =VLOOKUP($A13,'КРАТКИЙ ПРАЙС СПЛИТЫ'!$A:$M,6,0) -> 42/44/46 | I13: =VLOOKUP($A13,'КРАТКИЙ ПРАЙС СПЛИТЫ'!$A:$M,7,0) -> 500×1760×280 | J13: =VLOOKUP($A13,'КРАТКИЙ ПРАЙС СПЛИТЫ'!$A:$M,8,0) -> 860×670×310 | K13: =VLOOKUP($A13,'КРАТКИЙ ПРАЙС СПЛИТЫ'!$A:$M,9,0) -> 37/51 | L13: =O13-L14 -> 59600 | M13: =P13-M14 -> 50490 | N13: =Q13-N14 -> 33200 | O13: =VLOOKUP($A13,'КРАТКИЙ ПРАЙС СПЛИТЫ'!$A:$M,10,0) -> 148900 | P13: =VLOOKUP($A13,'КРАТКИЙ ПРАЙС СПЛИТЫ'!$A:$M,11,0) -> 126190 | Q13: =VLOOKUP($A13,'КРАТКИЙ ПРАЙС СПЛИТЫ'!$A:$M,12,0) -> 83000 | R13: =Q13*(1-1*'Скидка '!D$8) -> 83000
B14: НС-1291733 | C14: =RIGHT(D13,LEN(D13)-FIND("/",D13,1)) -> AUW-24H4SB | E14: 2.1 | F14: 3.1 | G14: А/А | K14: А/А | L14: =MROUND(O13*0.6,100) -> 89300 | M14: =MROUND(P13*0.6,100) -> 75700 | N14: =MROUND(Q13*0.6,100) -> 49800
A15: НС-1187876 | B15: НС-1064203 | C15: =LEFT(D15,FIND("/",D15,1)-1) -> AUF-48ER6SM | D15: =VLOOKUP($A15,'КРАТКИЙ ПРАЙС СПЛИТЫ'!$A:$M,2,0) -> AUF-48ER6SM/AUW-48H6SE1 | E15: =VLOOKUP($A15,'КРАТКИЙ ПРАЙС СПЛИТЫ'!$A:$M,3,0) -> 14 | F15: =VLOOKUP($A15,'КРАТКИЙ ПРАЙС СПЛИТЫ'!$A:$M,4,0) -> 15,0+3,6 | G15: =VLOOKUP($A15,'КРАТКИЙ ПРАЙС СПЛИТЫ'!$A:$M,5,0) -> B/B | H15: =VLOOKUP($A15,'КРАТКИЙ ПРАЙС СПЛИТЫ'!$A:$M,6,0) -> 48/50/52 | I15: =VLOOKUP($A15,'КРАТКИЙ ПРАЙС СПЛИТЫ'!$A:$M,7,0) -> 580x1870x380 | J15: =VLOOKUP($A15,'КРАТКИЙ ПРАЙС СПЛИТЫ'!$A:$M,8,0) -> 950x1050x340 | K15: =VLOOKUP($A15,'КРАТКИЙ ПРАЙС СПЛИТЫ'!$A:$M,9,0) -> 55/96 | L15: =O15-L16 -> 126300 | M15: =P15-M16 -> 106990 | N15: =Q15-N16 -> 68500 | O15: =VLOOKUP($A15,'КРАТКИЙ ПРАЙС СПЛИТЫ'!$A:$M,10,0) -> 241200 | P15: =VLOOKUP($A15,'КРАТКИЙ ПРАЙС СПЛИТЫ'!$A:$M,11,0) -> 204390 | Q15: =VLOOKUP($A15,'КРАТКИЙ ПРАЙС СПЛИТЫ'!$A:$M,12,0) -> 132300 | R15: =Q15*(1-1*'Скидка '!D$8) -> 132300
B16: НС-1064204 | C16: =RIGHT(D15,LEN(D15)-FIND("/",D15,1)) -> AUW-48H6SE1 | E16: 2.1 | F16: 3.1 | G16: А/А | K16: А/А | L16: =L41 -> 114900 | M16: =M41 -> 97400 | N16: =N41 -> 63800
A17: НС-1187877 | B17: НС-1064207 | C17: =LEFT(D17,FIND("/",D17,1)-1) -> AUF-60ER6SM | D17: =VLOOKUP($A17,'КРАТКИЙ ПРАЙС СПЛИТЫ'!$A:$M,2,0) -> AUF-60ER6SM/AUW-60H6SP1 | E17: =VLOOKUP($A17,'КРАТКИЙ ПРАЙС СПЛИТЫ'!$A:$M,3,0) -> 16 | F17: =VLOOKUP($A17,'КРАТКИЙ ПРАЙС СПЛИТЫ'!$A:$M,4,0) -> 17,0+3,6 | G17: =VLOOKUP($A17,'КРАТКИЙ ПРАЙС СПЛИТЫ'!$A:$M,5,0) -> B/D | H17: =VLOOKUP($A17,'КРАТКИЙ ПРАЙС СПЛИТЫ'!$A:$M,6,0) -> 48/50/52 | I17: =VLOOKUP($A17,'КРАТКИЙ ПРАЙС СПЛИТЫ'!$A:$M,7,0) -> 580x1870x380 | J17: =VLOOKUP($A17,'КРАТКИЙ ПРАЙС СПЛИТЫ'!$A:$M,8,0) -> 950x1386x340 | K17: =VLOOKUP($A17,'КРАТКИЙ ПРАЙС СПЛИТЫ'!$A:$M,9,0) -> 55/106 | L17: =O17-L18 -> 157300 | M17: =P17-M18 -> 133290 | N17: =Q17-N18 -> 87900 | O17: =VLOOKUP($A17,'КРАТКИЙ ПРАЙС СПЛИТЫ'!$A:$M,10,0) -> 286300 | P17: =VLOOKUP($A17,'КРАТКИЙ ПРАЙС СПЛИТЫ'!$A:$M,11,0) -> 242590 | Q17: =VLOOKUP($A17,'КРАТКИЙ ПРАЙС СПЛИТЫ'!$A:$M,12,0) -> 159500 | R17: =Q17*(1-1*'Скидка '!D$8) -> 159500
B18: НС-1064205 | C18: =RIGHT(D17,LEN(D17)-FIND("/",D17,1)) -> AUW-60H6SP1 | E18: 2.1 | F18: 3.1 | G18: А/А | K18: А/А | L18: =L44 -> 129000 | M18: =M44 -> 109300 | N18: =N44 -> 71600
C19: СПЛИТ-СИСТЕМЫ КАССЕТНОГО ТИПА HEAVY CLASSIC
F20: Круговая раздача воздуха | I20: Возможность организации подмеса свежего воздуха
F21: Рекордная длина трассы 35-60м | I21: ИК-пульт в комплекте
F22: Уровень шума от 36 дБ(А) | I22: Возможность подключения проводного пульта
F23: Дренажный насос с высотой подъема 1,2 м | I23: Таймер, функция I Feel, режимы Sleep, Smart, Super
F24: Уменьшенная толщина корпуса от 236 мм | I24: Диапазон работы на охлаждение/обогрев -15°С/-10°С*
F25: Автоматический перезапуск | I25: Специальный режим работы на отопление
F26: Вентилятор с назад загнутыми лопастями | I26: с увеличением расхода воздуха | P26: *кроме 12k
A27: НС-1187852 | B27: НС-1187074 | C27: =TRIM(LEFT(D27,FIND("|",D27,1)-1)) -> AUC-12HR4SAA | D27: =VLOOKUP($A27,'КРАТКИЙ ПРАЙС СПЛИТЫ'!$A:$M,2,0) -> AUC-12HR4SAA | AUC-650 | AUW-12H4SV | E27: =VLOOKUP($A27,'КРАТКИЙ ПРАЙС СПЛИТЫ'!$A:$M,3,0) -> 3.55 | F27: =VLOOKUP($A27,'КРАТКИЙ ПРАЙС СПЛИТЫ'!$A:$M,4,0) -> 3.81 | G27: =VLOOKUP($A27,'КРАТКИЙ ПРАЙС СПЛИТЫ'!$A:$M,5,0) -> А/А | H27: =VLOOKUP($A27,'КРАТКИЙ ПРАЙС СПЛИТЫ'!$A:$M,6,0) -> 36/40/42 | I27: =VLOOKUP($A27,'КРАТКИЙ ПРАЙС СПЛИТЫ'!$A:$M,7,0) -> 650x270x570 (650x30x650) | J27: =VLOOKUP('LCAC ON-OFF'!A27:A29,'КРАТКИЙ ПРАЙС СПЛИТЫ'!A162:H167,8,0) -> 715×482×240 | K27: =VLOOKUP($A27,'КРАТКИЙ ПРАЙС СПЛИТЫ'!$A:$M,9,0) -> 19(2,4)/28 | L27: =O27-L29-L28 -> 25800 | M27: =P27-M29-M28 -> 21890 | N27: =Q27-N29-N28 -> 14400 | O27: =VLOOKUP($A27,'КРАТКИЙ ПРАЙС СПЛИТЫ'!$A:$M,10,0) -> 86100 | P27: =VLOOKUP($A27,'КРАТКИЙ ПРАЙС СПЛИТЫ'!$A:$M,11,0) -> 72990 | Q27: =VLOOKUP($A27,'КРАТКИЙ ПРАЙС СПЛИТЫ'!$A:$M,12,0) -> 48000 | R27: =Q27*(1-1*'Скидка '!D$8) -> 48000
B28: НС-1223881 | C28: =TRIM(MID(D27,FIND("|",D27,1)+1,FIND(CHAR(1),SUBSTITUTE(D27,"|",CHAR(1),2),1)-FIND("|",D27,1)-1)) -> AUC-650 | E28: 3.1 | F28: 3.1 | G28: А/А | L28: =MROUND(O27*0.1,100) -> 8600 | M28: =MROUND(P27*0.1,100) -> 7300 | N28: =MROUND(Q27*0.1,100) -> 4800
B29: НС-1187075 | C29: =TRIM(RIGHT(D27,LEN(D27)-FIND(CHAR(1),SUBSTITUTE(D27,"|",CHAR(1),2),1))) -> AUW-12H4SV | L29: =MROUND(O27*0.6,100) -> 51700 | M29: =MROUND(P27*0.6,100) -> 43800 | N29: =MROUND(Q27*0.6,100) -> 28800
A30: НС-1187854 | B30: НС-1181792 | C30: =TRIM(LEFT(D30,FIND("|",D30,1)-1)) -> AUC-18HR4SAA1 | D30: =VLOOKUP($A30,'КРАТКИЙ ПРАЙС СПЛИТЫ'!$A:$M,2,0) -> AUC-18HR4SAA1 | AUC-650 | AUW-18H4SS | E30: =VLOOKUP($A30,'КРАТКИЙ ПРАЙС СПЛИТЫ'!$A:$M,3,0) -> 5 | F30: =VLOOKUP($A30,'КРАТКИЙ ПРАЙС СПЛИТЫ'!$A:$M,4,0) -> 5.8 | G30: =VLOOKUP($A30,'КРАТКИЙ ПРАЙС СПЛИТЫ'!$A:$M,5,0) -> С/А | H30: =VLOOKUP($A30,'КРАТКИЙ ПРАЙС СПЛИТЫ'!$A:$M,6,0) -> 42/44/46 | I30: =VLOOKUP($A30,'КРАТКИЙ ПРАЙС СПЛИТЫ'!$A:$M,7,0) -> 650x270x570 (650x30x650) | J30: =VLOOKUP(A30,'КРАТКИЙ ПРАЙС СПЛИТЫ'!A163:H167,8,0) -> 810×280×585 | K30: =VLOOKUP($A30,'КРАТКИЙ ПРАЙС СПЛИТЫ'!$A:$M,9,0) -> 20(2,4)/42 | L30: =O30-L32-L31 -> 30400 | M30: =P30-M32-M31 -> 25790 | N30: =Q30-N32-N31 -> 17000 | O30: =VLOOKUP($A30,'КРАТКИЙ ПРАЙС СПЛИТЫ'!$A:$M,10,0) -> 97600 | P30: =VLOOKUP($A30,'КРАТКИЙ ПРАЙС СПЛИТЫ'!$A:$M,11,0) -> 82690 | Q30: =VLOOKUP($A30,'КРАТКИЙ ПРАЙС СПЛИТЫ'!$A:$M,12,0) -> 54400 | R30: =Q30*(1-1*'Скидка '!D$8) -> 54400
B31: НС-1223881 | C31: =TRIM(MID(D30,FIND("|",D30,1)+1,FIND(CHAR(1),SUBSTITUTE(D30,"|",CHAR(1),2),1)-FIND("|",D30,1)-1)) -> AUC-650 | E31: 4.1 | F31: 3.1 | G31: А/А | L31: =L28 -> 8600 | M31: =M28 -> 7300 | N31: =N28 -> 4800
B32: НС-1181795 | C32: =TRIM(RIGHT(D30,LEN(D30)-FIND(CHAR(1),SUBSTITUTE(D30,"|",CHAR(1),2),1))) -> AUW-18H4SS | L32: =MROUND(O30*0.6,100) -> 58600 | M32: =MROUND(P30*0.6,100) -> 49600 | N32: =MROUND(Q30*0.6,100) -> 32600
A33: НС-1413682 | B33: НС-1405974 | C33: =TRIM(LEFT(D33,FIND("|",D33,1)-1)) -> AUC-24HR4SJA | D33: =VLOOKUP($A33,'КРАТКИЙ ПРАЙС СПЛИТЫ'!$A:$M,2,0) -> AUC-24HR4SJA | AUC-950R | AUW-24H4SF | E33: =VLOOKUP($A33,'КРАТКИЙ ПРАЙС СПЛИТЫ'!$A:$M,3,0) -> 7.3 | F33: =VLOOKUP($A33,'КРАТКИЙ ПРАЙС СПЛИТЫ'!$A:$M,4,0) -> 8 | G33: =VLOOKUP($A33,'КРАТКИЙ ПРАЙС СПЛИТЫ'!$A:$M,5,0) -> A/A | H33: =VLOOKUP($A33,'КРАТКИЙ ПРАЙС СПЛИТЫ'!$A:$M,6,0) -> 40/42/45 | I33: =VLOOKUP($A33,'КРАТКИЙ ПРАЙС СПЛИТЫ'!$A:$M,7,0) -> 840×236×840 (950×50×950) | J33: =VLOOKUP(A33,'КРАТКИЙ ПРАЙС СПЛИТЫ'!A164:H167,8,0) -> 860x665x310 | K33: =VLOOKUP($A33,'КРАТКИЙ ПРАЙС СПЛИТЫ'!$A:$M,9,0) -> 23,5(6,5)/51 | L33: =O33-L35-L34 -> 37200 | M33: =P33-M35-M34 -> 31490 | N33: =Q33-N35-N34 -> 20700 | O33: =VLOOKUP($A33,'КРАТКИЙ ПРАЙС СПЛИТЫ'!$A:$M,10,0) -> 124000 | P33: =VLOOKUP($A33,'КРАТКИЙ ПРАЙС СПЛИТЫ'!$A:$M,11,0) -> 105090 | Q33: =VLOOKUP($A33,'КРАТКИЙ ПРАЙС СПЛИТЫ'!$A:$M,12,0) -> 69100 | R33: =Q33*(1-1*'Скидка '!D$8) -> 69100
B34: НС-1405995 | C34: =TRIM(MID(D33,FIND("|",D33,1)+1,FIND(CHAR(1),SUBSTITUTE(D33,"|",CHAR(1),2),1)-FIND("|",D33,1)-1)) -> AUC-950R | E34: 5.1 | F34: 3.1 | G34: А/А | L34: =MROUND(O33*0.1,100) -> 12400 | M34: =MROUND(P33*0.1,100) -> 10500 | N34: =MROUND(Q33*0.1,100) -> 6900
B35: НС-1170516 | C35: =TRIM(RIGHT(D33,LEN(D33)-FIND(CHAR(1),SUBSTITUTE(D33,"|",CHAR(1),2),1))) -> AUW-24H4SF | L35: =MROUND(O33*0.6,100) -> 74400 | M35: =MROUND(P33*0.6,100) -> 63100 | N35: =MROUND(Q33*0.6,100) -> 41500
A36: НС-1413686 | B36: НС-1405977 | C36: =TRIM(LEFT(D36,FIND("|",D36,1)-1)) -> AUC-36HR4SKA | D36: =VLOOKUP($A36,'КРАТКИЙ ПРАЙС СПЛИТЫ'!$A:$M,2,0) -> AUC-36HR4SKA | AUC-950R | AUW-36H6SD | E36: =VLOOKUP($A36,'КРАТКИЙ ПРАЙС СПЛИТЫ'!$A:$M,3,0) -> 11 | F36: =VLOOKUP($A36,'КРАТКИЙ ПРАЙС СПЛИТЫ'!$A:$M,4,0) -> 11.5 | G36: =VLOOKUP($A36,'КРАТКИЙ ПРАЙС СПЛИТЫ'!$A:$M,5,0) -> A/A | H36: =VLOOKUP($A36,'КРАТКИЙ ПРАЙС СПЛИТЫ'!$A:$M,6,0) -> 45/48/50 | I36: =VLOOKUP($A36,'КРАТКИЙ ПРАЙС СПЛИТЫ'!$A:$M,7,0) -> 840×272×840 (950×50×950) | J36: =VLOOKUP(A36,'КРАТКИЙ ПРАЙС СПЛИТЫ'!A165:H167,8,0) -> 885×795×366 | K36: =VLOOKUP($A36,'КРАТКИЙ ПРАЙС СПЛИТЫ'!$A:$M,9,0) -> 28,0(6,5)/67 | L36: =O36-L38-L37 -> 51800 | M36: =P36-M38-M37 -> 43890 | N36: =Q36-N38-N37 -> 28800 | O36: =VLOOKUP($A36,'КРАТКИЙ ПРАЙС СПЛИТЫ'!$A:$M,10,0) -> 160400 | P36: =VLOOKUP($A36,'КРАТКИЙ ПРАЙС СПЛИТЫ'!$A:$M,11,0) -> 135890 | Q36: =VLOOKUP($A36,'КРАТКИЙ ПРАЙС СПЛИТЫ'!$A:$M,12,0) -> 89300 | R36: =Q36*(1-1*'Скидка '!D$8) -> 89300
B37: НС-1405995 | C37: =TRIM(MID(D36,FIND("|",D36,1)+1,FIND(CHAR(1),SUBSTITUTE(D36,"|",CHAR(1),2),1)-FIND("|",D36,1)-1)) -> AUC-950R | E37: 6.1 | F37: 3.1 | G37: А/А | L37: =L34 -> 12400 | M37: =M34 -> 10500 | N37: =N34 -> 6900
B38: НС-1154128 | C38: =TRIM(RIGHT(D36,LEN(D36)-FIND(CHAR(1),SUBSTITUTE(D36,"|",CHAR(1),2),1))) -> AUW-36H6SD | L38: =MROUND(O36*0.6,100) -> 96200 | M38: =MROUND(P36*0.6,100) -> 81500 | N38: =MROUND(Q36*0.6,100) -> 53600
A39: НС-1413687 | B39: НС-1405980 | C39: =TRIM(LEFT(D39,FIND("|",D39,1)-1)) -> AUC-48HR4SKA | D39: =VLOOKUP($A39,'КРАТКИЙ ПРАЙС СПЛИТЫ'!$A:$M,2,0) -> AUC-48HR4SKA | AUC-950R | AUW-48H6SE1 | E39: =VLOOKUP($A39,'КРАТКИЙ ПРАЙС СПЛИТЫ'!$A:$M,3,0) -> 14 | F39: =VLOOKUP($A39,'КРАТКИЙ ПРАЙС СПЛИТЫ'!$A:$M,4,0) -> 15 | G39: =VLOOKUP($A39,'КРАТКИЙ ПРАЙС СПЛИТЫ'!$A:$M,5,0) -> A/A | H39: =VLOOKUP($A39,'КРАТКИЙ ПРАЙС СПЛИТЫ'!$A:$M,6,0) -> 50/53/55 | I39: =VLOOKUP($A39,'КРАТКИЙ ПРАЙС СПЛИТЫ'!$A:$M,7,0) -> 840×272×840 (950×50×950) | J39: =VLOOKUP(A39,'КРАТКИЙ ПРАЙС СПЛИТЫ'!A166:H167,8,0) -> 950x1050x340 | K39: =VLOOKUP($A39,'КРАТКИЙ ПРАЙС СПЛИТЫ'!$A:$M,9,0) -> 28,0(6,5)/96 | L39: =O39-L41-L40 -> 64200 | M39: =P39-M41-M40 -> 54390 | N39: =Q39-N41-N40 -> 35600 | O39: =VLOOKUP($A39,'КРАТКИЙ ПРАЙС СПЛИТЫ'!$A:$M,10,0) -> 191500 | P39: =VLOOKUP($A39,'КРАТКИЙ ПРАЙС СПЛИТЫ'!$A:$M,11,0) -> 162290 | Q39: =VLOOKUP($A39,'КРАТКИЙ ПРАЙС СПЛИТЫ'!$A:$M,12,0) -> 106300 | R39: =Q39*(1-1*'Скидка '!D$8) -> 106300
B40: НС-1405995 | C40: =TRIM(MID(D39,FIND("|",D39,1)+1,FIND(CHAR(1),SUBSTITUTE(D39,"|",CHAR(1),2),1)-FIND("|",D39,1)-1)) -> AUC-950R | E40: 7.1 | F40: 3.1 | G40: А/А | L40: =L34 -> 12400 | M40: =M34 -> 10500 | N40: =N34 -> 6900
B41: НС-1064204 | C41: =TRIM(RIGHT(D39,LEN(D39)-FIND(CHAR(1),SUBSTITUTE(D39,"|",CHAR(1),2),1))) -> AUW-48H6SE1 | L41: =MROUND(O39*0.6,100) -> 114900 | M41: =MROUND(P39*0.6,100) -> 97400 | N41: =MROUND(Q39*0.6,100) -> 63800
...

Sheet LCAC INVERTER
C2: ='КРАТКИЙ ПРАЙС СПЛИТЫ'!B2 -> ПРАЙС-ЛИСТ ДЕЙСТВИТЕЛЕН С 01.01.2026
A3: НС-комплекта | B3: Кодблока | C3: Артикул | D3: Модель | E3: Мощность, кВт | G3: Класс энергоэф- фективности | H3: Уров. Шума внутреннего блока ДБ(A) | I3: Габариты блока (ДхВхГ), мм | K3: Вес нетто, кг | L3: РРЦ, руб | M3: РИЦ, руб | N3: Дилерская цена, руб. | O3: РРЦ, руб | P3: РИЦ, руб | Q3: Дилерская цена, руб. | R3: Ваша Спец цена, руб
E4: охл. | F4: нагр. | I4: Внутренний | J4: Наружный | L4: Блок | M4: Блок | N4: Блок | Q4: Комплект | R4: Комплект
C5: СПЛИТ-СИСТЕМЫ КАССЕТНОГО ТИПА HEAVY EU DC Inverter R32
F7: Независимое регулирование жалюзи с пульта | I7: Новый ИК-пульт в комплекте (RCH-RVD01)
F8: DC инверторный двигатель | I8: Встроенный датчик влажности
F9: Дренажный насос с высотой подъема до 1,2 м | I9: Автоматический перезапуск
F10: Возможность подключения воздуховода чистого воздуха | I10: Режим компенсации высоты помещения
F11: Система самодиагностики и защиты | I11: Подключение к BACnet/Modbus/центральному управлению (опция)
F12: Диапазон работы на охлаждение/нагрев -15°С / -20°С | I12: Работа с картой гостя
A13: НС-1619620 | B13: НС-1610676 | C13: =TRIM(LEFT(D13,FIND("|",D13,1)-1)) -> ACT-12UR4RCC8 | D13: =VLOOKUP($A13,'КРАТКИЙ ПРАЙС СПЛИТЫ'!$A:$M,2,0) -> ACT-12UR4RCC8 | PE-QEA/LD | AUW-12U4RS8 | E13: =VLOOKUP($A13,'КРАТКИЙ ПРАЙС СПЛИТЫ'!$A:$M,3,0) -> 3,50 (1,30-4,20) | F13: =VLOOKUP($A13,'КРАТКИЙ ПРАЙС СПЛИТЫ'!$A:$M,4,0) -> 4,00 (1,30-5,00) | G13: =VLOOKUP($A13,'КРАТКИЙ ПРАЙС СПЛИТЫ'!$A:$M,5,0) -> A++ / A++ | H13: =VLOOKUP($A13,'КРАТКИЙ ПРАЙС СПЛИТЫ'!$A:$M,6,0) -> 30/34/38 | I13: =VLOOKUP($A13,'КРАТКИЙ ПРАЙС СПЛИТЫ'!$A:$M,7,0) -> 570×215×570 (620×40×620) | J13: =VLOOKUP($A13,'КРАТКИЙ ПРАЙС СПЛИТЫ'!$A:$M,8,0) -> 810×580×280 | K13: =VLOOKUP($A13,'КРАТКИЙ ПРАЙС СПЛИТЫ'!$A:$M,9,0) -> 15,5 / 34,0 | L13: ='FREE MATCH'!K161 -> 51900 | M13: ='FREE MATCH'!L161 -> 43900 | N13: ='FREE MATCH'!M161 -> 28800 | O13: =VLOOKUP($A13,'КРАТКИЙ ПРАЙС СПЛИТЫ'!$A:$M,10,0) -> 134900 | P13: =VLOOKUP($A13,'КРАТКИЙ ПРАЙС СПЛИТЫ'!$A:$M,11,0) -> 114290 | Q13: =VLOOKUP($A13,'КРАТКИЙ ПРАЙС СПЛИТЫ'!$A:$M,12,0) -> 75100 | R13: =Q13*(1-1*'Скидка '!D$8) -> 75100
B14: НС-1610684 | C14: =TRIM(MID(D13,FIND("|",D13,1)+1,FIND(CHAR(1),SUBSTITUTE(D13,"|",CHAR(1),2),1)-FIND("|",D13,1)-1)) -> PE-QEA/LD | E14: 3.1 | F14: 3.1 | G14: А/А | L14: ='FREE MATCH'!K162 -> 16400 | M14: ='FREE MATCH'!L162 -> 13990 | N14: ='FREE MATCH'!M162 -> 9200
B15: НС-1494109 | C15: =TRIM(RIGHT(D13,LEN(D13)-FIND(CHAR(1),SUBSTITUTE(D13,"|",CHAR(1),2),1))) -> AUW-12U4RS8 | L15: =O13-L13-L14 -> 66600 | M15: =P13-M13-M14 -> 56400 | N15: =Q13-N13-N14 -> 37100
A16: НС-1619621 | B16: НС-1610677 | C16: =TRIM(LEFT(D16,FIND("|",D16,1)-1)) -> ACT-18UR4RCC8 | D16: =VLOOKUP($A16,'КРАТКИЙ ПРАЙС СПЛИТЫ'!$A:$M,2,0) -> ACT-18UR4RCC8 | PE-QEA/LD | AUW-18U4RS7 | E16: =VLOOKUP($A16,'КРАТКИЙ ПРАЙС СПЛИТЫ'!$A:$M,3,0) -> 5,00 (1,50-6,00) | F16: =VLOOKUP($A16,'КРАТКИЙ ПРАЙС СПЛИТЫ'!$A:$M,4,0) -> 5,50 (1,50-6,50) | G16: =VLOOKUP($A16,'КРАТКИЙ ПРАЙС СПЛИТЫ'!$A:$M,5,0) -> A++ / A+ | H16: =VLOOKUP($A16,'КРАТКИЙ ПРАЙС СПЛИТЫ'!$A:$M,6,0) -> 34/38/42 | I16: =VLOOKUP($A16,'КРАТКИЙ ПРАЙС СПЛИТЫ'!$A:$M,7,0) -> 570×215×570 (620×40×620) | J16: =VLOOKUP($A16,'КРАТКИЙ ПРАЙС СПЛИТЫ'!$A:$M,8,0) -> 810×580×280 | K16: =VLOOKUP($A16,'КРАТКИЙ ПРАЙС СПЛИТЫ'!$A:$M,9,0) -> 15,5 / 36,0 | L16: ='FREE MATCH'!K163 -> 54000 | M16: ='FREE MATCH'!L163 -> 45700 | N16: ='FREE MATCH'!M163 -> 30100 | O16: =VLOOKUP($A16,'КРАТКИЙ ПРАЙС СПЛИТЫ'!$A:$M,10,0) -> 140300 | P16: =VLOOKUP($A16,'КРАТКИЙ ПРАЙС СПЛИТЫ'!$A:$M,11,0) -> 118990 | Q16: =VLOOKUP($A16,'КРАТКИЙ ПРАЙС СПЛИТЫ'!$A:$M,12,0) -> 78200 | R16: =Q16*(1-1*'Скидка '!D$8) -> 78200
B17: НС-1610684 | C17: =TRIM(MID(D16,FIND("|",D16,1)+1,FIND(CHAR(1),SUBSTITUTE(D16,"|",CHAR(1),2),1)-FIND("|",D16,1)-1)) -> PE-QEA/LD | E17: 3.1 | F17: 3.1 | G17: А/А | L17: ='FREE MATCH'!K164 -> 16400 | M17: ='FREE MATCH'!L164 -> 13990 | N17: ='FREE MATCH'!M164 -> 9200
B18: НС-1610713 | C18: =TRIM(RIGHT(D16,LEN(D16)-FIND(CHAR(1),SUBSTITUTE(D16,"|",CHAR(1),2),1))) -> AUW-18U4RS7 | L18: =O16-L16-L17 -> 69900 | M18: =P16-M16-M17 -> 59300 | N18: =Q16-N16-N17 -> 38900
A19: НС-1619622 | B19: НС-1610679 | C19: =TRIM(LEFT(D19,FIND("|",D19,1)-1)) -> ACT-24UR4RJC8 | D19: =VLOOKUP($A19,'КРАТКИЙ ПРАЙС СПЛИТЫ'!$A:$M,2,0) -> ACT-24UR4RJC8 | PE-QFA/CD | AUW-24U4RJ7 | E19: =VLOOKUP($A19,'КРАТКИЙ ПРАЙС СПЛИТЫ'!$A:$M,3,0) -> 7,00 (2,00-8,50) | F19: =VLOOKUP($A19,'КРАТКИЙ ПРАЙС СПЛИТЫ'!$A:$M,4,0) -> 8,00 (2,00-9,50) | G19: =VLOOKUP($A19,'КРАТКИЙ ПРАЙС СПЛИТЫ'!$A:$M,5,0) -> A++ / A+ | H19: =VLOOKUP($A19,'КРАТКИЙ ПРАЙС СПЛИТЫ'!$A:$M,6,0) -> 37/40/43 | I19: =VLOOKUP($A19,'КРАТКИЙ ПРАЙС СПЛИТЫ'!$A:$M,7,0) -> 840×236×840 | J19: =VLOOKUP($A19,'КРАТКИЙ ПРАЙС СПЛИТЫ'!$A:$M,8,0) -> 860×670×310 | K19: =VLOOKUP($A19,'КРАТКИЙ ПРАЙС СПЛИТЫ'!$A:$M,9,0) -> 23,0 / 44,5 | L19: ='FREE MATCH'!K165 -> 67300 | M19: ='FREE MATCH'!L165 -> 56900 | N19: ='FREE MATCH'!M165 -> 37400 | O19: =VLOOKUP($A19,'КРАТКИЙ ПРАЙС СПЛИТЫ'!$A:$M,10,0) -> 170500 | P19: =VLOOKUP($A19,'КРАТКИЙ ПРАЙС СПЛИТЫ'!$A:$M,11,0) -> 144490 | Q19: =VLOOKUP($A19,'КРАТКИЙ ПРАЙС СПЛИТЫ'!$A:$M,12,0) -> 94900 | R19: =Q19*(1-1*'Скидка '!D$8) -> 94900
B20: НС-1610685 | C20: =TRIM(MID(D19,FIND("|",D19,1)+1,FIND(CHAR(1),SUBSTITUTE(D19,"|",CHAR(1),2),1)-FIND("|",D19,1)-1)) -> PE-QFA/CD | E20: 3.1 | F20: 3.1 | G20: А/А | L20: ='FREE MATCH'!K166 -> 16400 | M20: ='FREE MATCH'!L166 -> 13990 | N20: ='FREE MATCH'!M166 -> 9200
B21: НС-1610714 | C21: =TRIM(RIGHT(D19,LEN(D19)-FIND(CHAR(1),SUBSTITUTE(D19,"|",CHAR(1),2),1))) -> AUW-24U4RJ7 | L21: =O19-L19-L20 -> 86800 | M21: =P19-M19-M20 -> 73600 | N21: =Q19-N19-N20 -> 48300
A22: НС-1619624 | B22: НС-1610680 | C22: =TRIM(LEFT(D22,FIND("|",D22,1)-1)) -> AUC-36UR4RKC8 | D22: =VLOOKUP($A22,'КРАТКИЙ ПРАЙС СПЛИТЫ'!$A:$M,2,0) -> AUC-36UR4RKC8 | PE-QFA/CD | AUW-36U4RK7 | E22: =VLOOKUP($A22,'КРАТКИЙ ПРАЙС СПЛИТЫ'!$A:$M,3,0) -> 10,00 (2,70-12,00) | F22: =VLOOKUP($A22,'КРАТКИЙ ПРАЙС СПЛИТЫ'!$A:$M,4,0) -> 11,00 (2,70-13,00) | G22: =VLOOKUP($A22,'КРАТКИЙ ПРАЙС СПЛИТЫ'!$A:$M,5,0) -> A++ / A+ | H22: =VLOOKUP($A22,'КРАТКИЙ ПРАЙС СПЛИТЫ'!$A:$M,6,0) -> 42/46/50 | I22: =VLOOKUP($A22,'КРАТКИЙ ПРАЙС СПЛИТЫ'!$A:$M,7,0) -> 840×272×840 | J22: =VLOOKUP($A22,'КРАТКИЙ ПРАЙС СПЛИТЫ'!$A:$M,8,0) -> 900×750×340 | K22: =VLOOKUP($A22,'КРАТКИЙ ПРАЙС СПЛИТЫ'!$A:$M,9,0) -> 26,0 / 55,0 | L22: =O22-L24-L23 -> 81200 | M22: =P22-M24-M23 -> 68726 | N22: =Q22-N24-N23 -> 45360 | O22: =VLOOKUP($A22,'КРАТКИЙ ПРАЙС СПЛИТЫ'!$A:$M,10,0) -> 244000 | P22: =VLOOKUP($A22,'КРАТКИЙ ПРАЙС СПЛИТЫ'!$A:$M,11,0) -> 206790 | Q22: =VLOOKUP($A22,'КРАТКИЙ ПРАЙС СПЛИТЫ'!$A:$M,12,0) -> 136400 | R22: =Q22*(1-1*'Скидка '!D$8) -> 136400
B23: НС-1610685 | C23: =TRIM(MID(D22,FIND("|",D22,1)+1,FIND(CHAR(1),SUBSTITUTE(D22,"|",CHAR(1),2),1)-FIND("|",D22,1)-1)) -> PE-QFA/CD | E23: 3.1 | F23: 3.1 | G23: А/А | L23: =L20 -> 16400 | M23: =M20 -> 13990 | N23: =N20 -> 9200
B24: НС-1610715 | C24: =TRIM(RIGHT(D22,LEN(D22)-FIND(CHAR(1),SUBSTITUTE(D22,"|",CHAR(1),2),1))) -> AUW-36U4RK7 | L24: =O22*0.6 -> 146400 | M24: =P22*0.6 -> 124074 | N24: =Q22*0.6 -> 81840
