Workbook
Name скидка_на_VRF_Приточные_установки: #REF!
Name скидка_на_VRF_Приточные_установки: #REF!
Name скидка_на_VRF_Приточные_установки: #REF!

Sheet Лист1
A1: Код | B1: Артикул | C1: BASE | D1: РИЦ | G1: дата | H1: 46023
A2: НС-1697689 | B2: H09S1D.NS1R | C2: 29485 | D2: 35800
A3: НС-1697691 | B3: H09S1D.U12R | C3: 44634 | D3: 54190
A4: НС-1697692 | B4: H12S1D.NS1R | C4: 37720 | D4: 45500
A5: НС-1697693 | B5: H12S1D.U12R | C5: 52666 | D5: 63490
A6: НС-1697694 | B6: H18S1D.NS1R | C6: 54496 | D6: 64000
A7: НС-1697695 | B7: H18S1D.U18R | C7: 77575 | D7: 90990
A8: НС-1697696 | B8: H24S1D.NS1R | C8: 64256 | D8: 75100
A9: НС-1697697 | B9: H24S1D.U24R | C9: 98315 | D9: 114890
A10: НС-1606433 | B10: AC09BK.NSJR | C10: 33043 | D10: 39000
A11: НС-1606434 | B11: AC09BK.UA3R | C11: 45854 | D11: 53990
A12: НС-1606436 | B12: AC12BK.NSJR | C12: 34975 | D12: 40900
A13: НС-1606438 | B13: AC12BK.UA3R | C13: 48904 | D13: 57090
... A66: НС-1275535 | B66: PWFMDD200.ENCXLEU | C66: 9151 | D66: 10900

Sheet Deluxe Pro
B67: =Лист1!H1 -> 46023 | M67: Ваша скидка | N67: 0
A68: НС-код комплект | B68: Модель | C68: НС-код блок | D68: Наименование | F68: Мощность, кВт | H68: Уровень звукового давления ВБ | I68: Класс энерго-эффектив-ности | J68: Габариты блока (ДхВхГ), мм | K68: Вес нетто, (кг) | L68: РИЦ, руб. | M68: Дилерская цена, руб. | N68: Ваша спец. цена, руб.
F69: охлаждение | G69: нагрев
B70: Deluxe Pro
A71: НС-1697698 | B71: 9K | C71: НС-1697689 | D71: H09S1D.NS1R | E71: внутренний блок | F71: 2,50 (0,89 - 3,8) | G71: 3,2 (0,65 - 4,9) | H71: 19/27/35/40/47 | I71: A+++/А++ | J71: 895×307×235 | K71: 11 | L71: =VLOOKUP(C71,Лист1!$A$1:$D$130,4,FALSE)+VLOOKUP(C72,Лист1!$A$1:$D$130,4,FALSE) -> 89990 | M71: =VLOOKUP(C71,Лист1!$A$1:$D$130,3,FALSE)+VLOOKUP(C72,Лист1!$A$1:$D$130,3,FALSE) -> 74119 | N71: =M71*(1-$N$67) -> 74119
C72: НС-1697691 | D72: H09S1D.U12R | E72: наружный блок | J72: 717×495×230 | K72: 25.1
A73: НС-1697699 | B73: 12K | C73: НС-1697692 | D73: H12S1D.NS1R | E73: внутренний блок | F73: 3,5 (0,89 - 4,2) | G73: 4,0 (0,65 - 5,4) | H73: 19/27/35/40/47 | I73: A+++/А++ | J73: 895×307×235 | K73: 11 | L73: =VLOOKUP(C73,Лист1!$A$1:$D$130,4,FALSE)+VLOOKUP(C74,Лист1!$A$1:$D$130,4,FALSE) -> 108990 | M73: =VLOOKUP(C73,Лист1!$A$1:$D$130,3,FALSE)+VLOOKUP(C74,Лист1!$A$1:$D$130,3,FALSE) -> 90386 | N73: =M73*(1-$N$67) -> 90386
C74: НС-1697693 | D74: H12S1D.U12R | E74: наружный блок | J74: 717×495×230 | K74: 25.1
A75: НС-1697700 | B75: 18K | C75: НС-1697694 | D75: H18S1D.NS1R | E75: внутренний блок | F75: 5,0 (0,9 - 5,5) | G75: 5,8 (0,9 - 6,40) | H75: 29/34/39/44/49 | I75: A++/А+ | J75: 895×307×235 | K75: 12.8 | L75: =VLOOKUP(C75,Лист1!$A$1:$D$130,4,FALSE)+VLOOKUP(C76,Лист1!$A$1:$D$130,4,FALSE) -> 154990 | M75: =VLOOKUP(C75,Лист1!$A$1:$D$130,3,FALSE)+VLOOKUP(C76,Лист1!$A$1:$D$130,3,FALSE) -> 132071 | N75: =M75*(1-$N$67) -> 132071
C76: НС-1697695 | D76: H18S1D.U18R | E76: наружный блок | J76: 770×545×288 | K76: 34.4
A77: НС-1697701 | B77: 24K | C77: НС-1697696 | D77: H24S1D.NS1R | E77: внутренний блок | F77: 6,6 (0,9 - 7,72) | G77: 7,5 (0,9 - 8,64) | H77: 31/34/42/47/51 | I77: A++/А+ | J77: 895×307×235 | K77: 12.8 | L77: =VLOOKUP(C77,Лист1!$A$1:$D$130,4,FALSE)+VLOOKUP(C78,Лист1!$A$1:$D$130,4,FALSE) -> 189990 | M77: =VLOOKUP(C77,Лист1!$A$1:$D$130,3,FALSE)+VLOOKUP(C78,Лист1!$A$1:$D$130,3,FALSE) -> 162571 | N77: =M77*(1-$N$67) -> 162571
C78: НС-1697697 | D78: H24S1D.U24R | E78: наружный блок | J78: 870×650×330 | K78: 44

Sheet ARTCOOL Mirror
B67: =Лист1!H1 -> 46023 | M67: Ваша скидка | N67: 0
A68: НС-код комплект | B68: Модель | C68: НС-код блок | D68: Наименование | F68: Мощность, кВт | H68: Уровень звукового давления ВБ | I68: Класс энерго-эффектив-ности | J68: Габариты блока (ДхВхГ), мм | K68: Вес нетто, (кг) | L68: РИЦ, руб. | M68: Дилерская цена, руб. | N68: Ваша спец. цена, руб.
F69: охлаждение | G69: нагрев
B70: ARTCOOL Mirror
A71: НС-1606456 | B71: 9K | C71: НС-1606433 | D71: AC09BK.NSJR | E71: внутренний блок | F71: 2,50 (0,89 - 3,70) | G71: 3,3 (0,89 - 4,10) | H71: 19/27/35/45 | I71: A++/А+ | J71: 837х308х189 | K71: 9.9 | L71: =VLOOKUP(C71,Лист1!$A$1:$D$130,4,FALSE)+VLOOKUP(C72,Лист1!$A$1:$D$130,4,FALSE) -> 92990 | M71: =VLOOKUP(C71,Лист1!$A$1:$D$130,3,FALSE)+VLOOKUP(C72,Лист1!$A$1:$D$130,3,FALSE) -> 78897 | N71: =M71*(1-$N$67) -> 78897
C72: НС-1606434 | D72: AC09BK.UA3R | E72: наружный блок | J72: 717×483×230 | K72: 26
A73: НС-1606457 | B73: 12K | C73: НС-1606436 | D73: AC12BK.NSJR | E73: внутренний блок | F73: 3,5 (0,89 - 4,04) | G73: 4,0 (0,89 - 5,10) | H73: 19/27/35/45 | I73: A++/А+ | J73: 837х308х189 | K73: 9.9 | L73: =VLOOKUP(C73,Лист1!$A$1:$D$130,4,FALSE)+VLOOKUP(C74,Лист1!$A$1:$D$130,4,FALSE) -> 97990 | M73: =VLOOKUP(C73,Лист1!$A$1:$D$130,3,FALSE)+VLOOKUP(C74,Лист1!$A$1:$D$130,3,FALSE) -> 83879 | N73: =M73*(1-$N$67) -> 83879
C74: НС-1606438 | D74: AC12BK.UA3R | E74: наружный блок | J74: 717×483×230 | K74: 26

Sheet ProCool
B41: =Лист1!H1 -> 46023 | M41: Ваша скидка | N41: 0
A42: НС-код комплект | B42: Модель | C42: НС-код блок | D42: Наименование | F42: Мощность, кВт | H42: Уровень звукового давления ВБ | I42: Класс энерго-эффектив-ности | J42: Габариты блока (ДхВхГ), мм | K42: Вес нетто, (кг) | L42: РИЦ, руб. | M42: Дилерская цена, руб. | N42: Ваша спец. цена, руб.
F43: охлаждение | G43: нагрев
B44: ProCool
A45: НС-1344689 | B45: 7K | C45: НС-1198217 | D45: B07TS.NSJ | E45: внутренний блок | F45: 2,14 (0,88-3,05) | G45: 2,50 (0,88-4,04) | H45: 19/28/32/36 | I45: A/А | J45: 837х308х189 | K45: 8.6 | L45: =VLOOKUP(C45,Лист1!$A$1:$D$130,4,FALSE)+VLOOKUP(C46,Лист1!$A$1:$D$130,4,FALSE) -> 59990 | M45: =VLOOKUP(C45,Лист1!$A$1:$D$130,3,FALSE)+VLOOKUP(C46,Лист1!$A$1:$D$130,3,FALSE) -> 48701 | N45: =M45*(1-$N$41) -> 48701
C46: НС-1198218 | D46: B07TS.UA3 | E46: наружный блок | J46: 717×495×230 | K46: 26.4
A47: НС-1344693 | B47: 9K | C47: НС-1198219 | D47: B09TS.NSJ | E47: внутренний блок | F47: 2,70 (0,88-3,46) | G47: 2,93 (0,88-4,04) | H47: 19/28/36/42 | I47: A/А | J47: 837х308х189 | K47: 8.6 | L47: =VLOOKUP(C47,Лист1!$A$1:$D$130,4,FALSE)+VLOOKUP(C48,Лист1!$A$1:$D$130,4,FALSE) -> 64990 | M47: =VLOOKUP(C47,Лист1!$A$1:$D$130,3,FALSE)+VLOOKUP(C48,Лист1!$A$1:$D$130,3,FALSE) -> 52768 | N47: =M47*(1-$N$41) -> 52768
C48: НС-1198221 | D48: B09TS.UA3 | E48: наружный блок | J48: 717×495×230 | K48: 26.4
A49: НС-1344695 | B49: 12K | C49: НС-1198222 | D49: B12TS.NSJ | E49: внутренний блок | F49: 3,52 (0,88-3,87) | G49: 3,52 (0,88-4,04) | H49: 19/28/36/42 | I49: A/А | J49: 837х308х189 | K49: 8.6 | L49: =VLOOKUP(C49,Лист1!$A$1:$D$130,4,FALSE)+VLOOKUP(C50,Лист1!$A$1:$D$130,4,FALSE) -> 72990 | M49: =VLOOKUP(C49,Лист1!$A$1:$D$130,3,FALSE)+VLOOKUP(C50,Лист1!$A$1:$D$130,3,FALSE) -> 59885 | N49: =M49*(1-$N$41) -> 59885
C50: НС-1198224 | D50: B12TS.UA3 | E50: наружный блок | J50: 717×495×230 | K50: 26.4
A51: НС-1347782 | B51: 18K | C51: НС-1198226 | D51: B18TS.NSK | E51: внутренний блок | F51: 5,28 (1,08-5,36) | G51: 5,42 (1,08-6,10) | H51: 32/38/43/55 | I51: A/А | J51: 998x345x210 | K51: 11.5 | L51: =VLOOKUP(C51,Лист1!$A$1:$D$130,4,FALSE)+VLOOKUP(C52,Лист1!$A$1:$D$130,4,FALSE) -> 99990 | M51: =VLOOKUP(C51,Лист1!$A$1:$D$130,3,FALSE)+VLOOKUP(C52,Лист1!$A$1:$D$130,3,FALSE) -> 82252 | N51: =M51*(1-$N$41) -> 82252
C52: НС-1198227 | D52: B18TS.UL2 | E52: наружный блок | J52: 770x545x288 | K52: 34.2
A53: НС-1347783 | B53: 24K | C53: НС-1374053 | D53: B24TS.NSKC | E53: внутренний блок | F53: 6,45 (1,03-7,18) | G53: 6,45 (1,03-7,18) | H53: 32/38/43/56 | I53: A/B | J53: 998x345x210 | K53: 13 | L53: =VLOOKUP(C53,Лист1!$A$1:$D$130,4,FALSE)+VLOOKUP(C54,Лист1!$A$1:$D$130,4,FALSE) -> 119990 | M53: =VLOOKUP(C53,Лист1!$A$1:$D$130,3,FALSE)+VLOOKUP(C54,Лист1!$A$1:$D$130,3,FALSE) -> 101570 | N53: =M53*(1-$N$41) -> 101570
C54: НС-1374054 | D54: B24TS.U24C | E54: наружный блок | J54: 870x650x330 | K54: 42.7

Sheet MegaCool
B37: =Лист1!H1 -> 46023
A38: НС-код комплект | B38: Модель | C38: НС-код блок | D38: Наименование | F38: Мощность, кВт | H38: Уровень звукового давления ВБ | I38: Класс энерго-эффектив-ности | J38: Габариты блока (ДхВхГ), мм | K38: Вес нетто, (кг) | L38: РИЦ, руб. | M38: Дилерская цена (фиксированная), руб.
F39: охлаждение | G39: нагрев
B40: MegaCool
A41: НС-1606451 | B41: 7K | C41: НС-1606371 | D41: P07EP2.NSAR | E41: внутренний блок | F41: 2,14 (0,88-3,05) | G41: 2,50 (0,88-3,70) | H41: 21/28/36/42 | I41: A/А | J41: 754×308×189 | K41: 7.8 | L41: =VLOOKUP(C41,Лист1!$A$1:$D$130,4,FALSE)+VLOOKUP(C42,Лист1!$A$1:$D$130,4,FALSE) -> 42990 | M41: =VLOOKUP(C41,Лист1!$A$1:$D$130,3,FALSE)+VLOOKUP(C42,Лист1!$A$1:$D$130,3,FALSE) -> 30299
C42: НС-1606373 | D42: P07EP2.UA3R | E42: наружный блок | J42: 717×495×230 | K42: 25.7
A43: НС-1606452 | B43: 9K | C43: НС-1606374 | D43: P09EP2.NSAR | E43: внутренний блок | F43: 2,64 (0,88-3,25) | G43: 2,70 (0,88-3,70) | H43: 21/28/36/42 | I43: A/А | J43: 754×308×189 | K43: 7.8 | L43: =VLOOKUP(C43,Лист1!$A$1:$D$130,4,FALSE)+VLOOKUP(C44,Лист1!$A$1:$D$130,4,FALSE) -> 45990 | M43: =VLOOKUP(C43,Лист1!$A$1:$D$130,3,FALSE)+VLOOKUP(C44,Лист1!$A$1:$D$130,3,FALSE) -> 31417
C44: НС-1606375 | D44: P09EP2.UA3R | E44: наружный блок | J44: 717×495×230 | K44: 25.7
A45: НС-1606454 | B45: 18K | C45: НС-1606384 | D45: P18EP1.NSK | E45: внутренний блок | F45: 5,28 (1,08-5,36) | G45: 5,42 (1,08-6,10) | H45: 32/38/43/55 | I45: A/А | J45: 998x345x210 | K45: 11.4 | L45: =VLOOKUP(C45,Лист1!$A$1:$D$130,4,FALSE)+VLOOKUP(C46,Лист1!$A$1:$D$130,4,FALSE) -> 79990 | M45: =VLOOKUP(C45,Лист1!$A$1:$D$130,3,FALSE)+VLOOKUP(C46,Лист1!$A$1:$D$130,3,FALSE) -> 57139
C46: НС-1606385 | D46: P18EP1.UL2 | E46: наружный блок | J46: 770x545x288 | K46: 34
A47: НС-1606455 | B47: 24K | C47: НС-1606386 | D47: P24EP.NSKC | E47: внутренний блок | F47: 6,45 (1,03-7,18) | G47: 6,45 (1,03-7,18) | H47: 32/38/43/48 | I47: A/B | J47: 998x345x210 | K47: 11.7 | L47: =VLOOKUP(C47,Лист1!$A$1:$D$130,4,FALSE)+VLOOKUP(C48,Лист1!$A$1:$D$130,4,FALSE) -> 99990 | M47: =VLOOKUP(C47,Лист1!$A$1:$D$130,3,FALSE)+VLOOKUP(C48,Лист1!$A$1:$D$130,3,FALSE) -> 69645
C48: НС-1606393 | D48: P24EP.U24C | E48: наружный блок | J48: 870x650x330 | K48: 42.9

Sheet PROMULTI 2.0 (R32)
B2: =Лист1!H1 -> 46023 | O2: Ваша скидка | P2: 0
A3: НС-код комплект | B3: Модель | C3: НС-код блок | D3: Блок | E3: Тип блока | F3: Мощность, кВт | H3: SEER | I3: SCOP | J3: Габариты блока (ДхВхГ), мм | K3: Вес, кг | L3: Диаметры труб, мм | M3: ВБ: Кол-во (Мощность), кВт мин./макс. | N3: РИЦ, руб. | O3: Дилерская цена, руб. | P3: Ваша спец. цена, руб.
F4: охлаждение | G4: нагрев
B5: Наружные блоки мульти сплит-систем (R32)
A11: НС-1705604 | B11: 15к | C11: НС-1705604 | D11: MU2R15.U13 | E11: наружный блок (на 2 внутр.) | F11: 4,1 (0,88 - 4,72) | G11: 4,69 (0,97 - 5,39) | H11: 8,6/A+++ | I11: 4,6/A++ | J11: 770×545×288 | K11: 32.5 | L11: 6,35 / 9,52 | M11: 2/2 (3,0/6,1) | N11: =VLOOKUP(C11,Лист1!$A$1:$D$130,4,FALSE) -> 125900 | O11: =VLOOKUP(C11,Лист1!$A$1:$D$130,3,FALSE) -> 105331 | P11: =O11*(1-$P$2) -> 105331
A12: НС-1705605 | B12: 17к | C12: НС-1705605 | D12: MU2R17.U13 | E12: наружный блок (на 2 внутр.) | F12: 4,69 (0,88 - 5,39) | G12: 5,1 (0,97 - 5,51) | H12: 8,5/A+++ | I12: 4,6/A++ | J12: 770×545×288 | K12: 32.5 | L12: 6,35 / 9,52 | M12: 2/2 (3,0/7,0) | N12: =VLOOKUP(C12,Лист1!$A$1:$D$130,4,FALSE) -> 139600 | O12: =VLOOKUP(C12,Лист1!$A$1:$D$130,3,FALSE) -> 116819 | P12: =O12*(1-$P$2) -> 116819
A13: НС-1705606 | B13: 19к | C13: НС-1705606 | D13: MU3R19.U23 | E13: наружный блок (на 3 внутр.) | F13: 5,27 (1,06 - 6,33) | G13: 6,33 (1,17 - 7,33) | H13: 8,6/A+++ | I13: 4,7/A++ | J13: 870×650×330 | K13: 44.5 | L13: 6,35 / 9,52 | M13: 2/3 (3,0/8,7) | N13: =VLOOKUP(C13,Лист1!$A$1:$D$130,4,FALSE) -> 166300 | O13: =VLOOKUP(C13,Лист1!$A$1:$D$130,3,FALSE) -> 139187 | P13: =O13*(1-$P$2) -> 139187
A14: НС-1705608 | B14: 21к | C14: НС-1705608 | D14: MU3R21.U23 | E14: наружный блок (на 3 внутр.) | F14: 6,15 (1,06 - 7,33) | G14: 7,03 (1,17 - 7,8) | H14: 8,5/A+++ | I14: 4,7/A++ | J14: 870×650×330 | K14: 44.5 | L14: 6,35 / 9,52 | M14: 2/3 (3,0/9,6) | N14: =VLOOKUP(C14,Лист1!$A$1:$D$130,4,FALSE) -> 179700 | O14: =VLOOKUP(C14,Лист1!$A$1:$D$130,3,FALSE) -> 150370 | P14: =O14*(1-$P$2) -> 150370
A15: НС-1705609 | B15: 25к | C15: НС-1705609 | D15: MU4R25.U22 | E15: наружный блок (на 4 внутр.) | F15: 7,03 (1,06 - 8,50) | G15: 8,09 (1,17 - 9,09) | H15: 8,0/A++ | I15: 4,4/A+ | J15: 870×650×330 | K15: 47 | L15: 6,35 / 9,52 | M15: 2/4 (3,0/11,4) | N15: =VLOOKUP(C15,Лист1!$A$1:$D$130,4,FALSE) -> 222200 | O15: =VLOOKUP(C15,Лист1!$A$1:$D$130,3,FALSE) -> 185955 | P15: =O15*(1-$P$2) -> 185955
A16: НС-1705610 | B16: 27к | C16: НС-1705610 | D16: MU4R27.U42 | E16: наружный блок (на 4 внутр.) | F16: 7,9 (1,32 - 9,50) | G16: 9,09 (1,47 - 10,6) | H16: 8,0/A++ | I16: 4,3/A+ | J16: 950×834×330 | K16: 63.5 | L16: 6,35 / 9,52 | M16: 2/4 (3,0/12,0) | N16: =VLOOKUP(C16,Лист1!$A$1:$D$130,4,FALSE) -> 230700 | O16: =VLOOKUP(C16,Лист1!$A$1:$D$130,3,FALSE) -> 193072 | P16: =O16*(1-$P$2) -> 193072
A17: НС-1705611 | B17: 30к | C17: НС-1705611 | D17: MU5R30.U42 | E17: наружный блок (на 5 внутр.) | F17: 8,8 (1,32 - 10,6) | G17: 10,1 (1,47 - 12,1) | H17: 8,2/A++ | I17: 4,3/A+ | J17: 950×834×330 | K17: 64.1 | L17: 6,35 / 9,52 | M17: 2/5 (3,0/14,0) | N17: =VLOOKUP(C17,Лист1!$A$1:$D$130,4,FALSE) -> 248900 | O17: =VLOOKUP(C17,Лист1!$A$1:$D$130,3,FALSE) -> 208322 | P17: =O17*(1-$P$2) -> 208322
A18: НС-1702401 | B18: 40к | C18: НС-1702401 | D18: MU5R40.U42 | E18: наружный блок (на 5 внутр.) | F18: 11,2 (1,32 - 14,65) | G18: 12,51 (1,47 - 15,97) | H18: 7,5/A++ | I18: 4,4/A+ | J18: 950×834×330 | K18: 74 | L18: 6,35 / 9,52 | M18: 2/5 (3,0/21,0) | N18: =VLOOKUP(C18,Лист1!$A$1:$D$130,4,FALSE) -> 313300 | O18: =VLOOKUP(C18,Лист1!$A$1:$D$130,3,FALSE) -> 262207 | P18: =O18*(1-$P$2) -> 262207
B19: Внутренние блоки мульти сплит-систем настенного типа серии Standard
A25: НС-1199012 | B25: 7k | C25: НС-1199012 | D25: PM07SP.NSJR0 | E25: внутренний блок | F25: 2.1 | G25: 2,3 | H25: - | I25: - | J25: 837×308×189 | K25: 8.7 | L25: 6,35 / 9,52 | M25: - | N25: =VLOOKUP(C25,Лист1!$A$1:$D$130,4,FALSE) -> 33300 | O25: =VLOOKUP(C25,Лист1!$A$1:$D$130,3,FALSE) -> 27858 | P25: =O25*(1-$P$2) -> 27858
A26: НС-1199013 | B26: 9k | C26: НС-1199013 | D26: PM09SP.NSJ | E26: внутренний блок | F26: 2,5 | G26: 3,2 | H26: - | I26: - | J26: 837×308×189 | K26: 8.7 | L26: 6,35 / 9,52 | M26: - | N26: =VLOOKUP(C26,Лист1!$A$1:$D$130,4,FALSE) -> 35700 | O26: =VLOOKUP(C26,Лист1!$A$1:$D$130,3,FALSE) -> 29891 | P26: =O26*(1-$P$2) -> 29891
A27: НС-1199015 | B27: 12k | C27: НС-1199015 | D27: PM12SP.NSJR0 | E27: внутренний блок | F27: 3.5 | G27: 3,8 | H27: - | I27: - | J27: 837×308×189 | K27: 8.7 | L27: 6,35 / 9,52 | M27: - | N27: =VLOOKUP(C27,Лист1!$A$1:$D$130,4,FALSE) -> 38000 | O27: =VLOOKUP(C27,Лист1!$A$1:$D$130,3,FALSE) -> 31823 | P27: =O27*(1-$P$2) -> 31823
A28: НС-1199020 | B28: 18k | C28: НС-1199020 | D28: PM18SP.NSKR0 | E28: внутренний блок | F28: 5,0 | G28: 5,8 | H28: - | I28: - | J28: 998×345×210 | K28: 12 | L28: 6,35 / 12,7 | M28: - | N28: =VLOOKUP(C28,Лист1!$A$1:$D$130,4,FALSE) -> 48500 | O28: =VLOOKUP(C28,Лист1!$A$1:$D$130,3,FALSE) -> 40567 | P28: =O28*(1-$P$2) -> 40567
B29: Внутренние блоки мульти сплит-систем канального типа
A35: НС-1298640 | B35: 9k | C35: НС-1298640 | D35: CL09R.N20 | E35: внутренний блок | F35: 2,5 | G35: 3,2 | H35: - | I35: - | J35: 900×190×700 | K35: 24 | L35: 6,35 / 9,52 | M35: - | N35: =VLOOKUP(C35,Лист1!$A$1:$D$130,4,FALSE) -> 79500 | O35: =VLOOKUP(C35,Лист1!$A$1:$D$130,3,FALSE) -> 66594 | P35: =O35*(1-$P$2) -> 66594
A36: НС-1305287 | B36: 12k | C36: НС-1305287 | D36: CL12R.N20 | E36: внутренний блок | F36: 3.5 | G36: 4,0 | H36: - | I36: - | J36: 900×190×700 | K36: 24 | L36: 6,35 / 9,52 | M36: - | N36: =VLOOKUP(C36,Лист1!$A$1:$D$130,4,FALSE) -> 89800 | O36: =VLOOKUP(C36,Лист1!$A$1:$D$130,3,FALSE) -> 75135 | P36: =O36*(1-$P$2) -> 75135
A37: НС-1305289 | B37: 18k | C37: НС-1305289 | D37: CL18R.N20 | E37: внутренний блок | F37: 5,0 | G37: 5,8 | H37: - | I37: - | J37: 900×190×700 | K37: 24 | L37: 6,35 / 12,7 | M37: - | N37: =VLOOKUP(C37,Лист1!$A$1:$D$130,4,FALSE) -> 91900 | O37: =VLOOKUP(C37,Лист1!$A$1:$D$130,3,FALSE) -> 77168 | P37: =O37*(1-$P$2) -> 77168
A38: НС-1340917 | C38: НС-1340917 | D38: PWLSSB21H.ENCXLEU | F38: Беспроводной пульт | N38: =VLOOKUP(C38,Лист1!$A$1:$D$130,4,FALSE) -> 16900 | O38: =VLOOKUP(C38,Лист1!$A$1:$D$130,3,FALSE) -> 14133 | P38: =O38*(1-$P$2) -> 14133
A39: НС-1275535 | C39: НС-1275535 | D39: PWFMDD200.ENCXLEU | F39: Wi-Fi модуль | N39: =VLOOKUP(C39,Лист1!$A$1:$D$130,4,FALSE) -> 10900 | O39: =VLOOKUP(C39,Лист1!$A$1:$D$130,3,FALSE) -> 9151 | P39: =O39*(1-$P$2) -> 9151
B40: Внутренние блоки мульти сплит-систем настенного типа серии Deluxe Pro
A46: НС-1697689 | B46: 9k | C46: НС-1697689 | D46: H09S1D.NS1R | E46: внутренний блок | F46: 2,5 | G46: 3,2 | H46: - | I46: - | J46: 895×307×235 | K46: 11 | L46: 6,35 / 9,52 | M46: - | N46: =VLOOKUP(C46,Лист1!$A$1:$D$130,4,FALSE) -> 35800 | O46: =VLOOKUP(C46,Лист1!$A$1:$D$130,3,FALSE) -> 29485 | P46: =O46*(1-$P$2) -> 29485
A47: НС-1697692 | B47: 12k | C47: НС-1697692 | D47: H12S1D.NS1R | E47: внутренний блок | F47: 3.5 | G47: 4,0 | H47: - | I47: - | J47: 895×307×235 | K47: 11 | L47: 6,35 / 9,52 | M47: - | N47: =VLOOKUP(C47,Лист1!$A$1:$D$130,4,FALSE) -> 45500 | O47: =VLOOKUP(C47,Лист1!$A$1:$D$130,3,FALSE) -> 37720 | P47: =O47*(1-$P$2) -> 37720
A48: НС-1697694 | B48: 18k | C48: НС-1697694 | D48: H18S1D.NS1R | E48: внутренний блок | F48: 5,0 | G48: 5,8 | H48: - | I48: - | J48: 895×307×235 | K48: 12.8 | L48: 6,35 / 12,7 | M48: - | N48: =VLOOKUP(C48,Лист1!$A$1:$D$130,4,FALSE) -> 64000 | O48: =VLOOKUP(C48,Лист1!$A$1:$D$130,3,FALSE) -> 54496 | P48: =O48*(1-$P$2) -> 54496
A49: НС-1697696 | B49: 24k | C49: НС-1697696 | D49: H24S1D.NS1R | E49: внутренний блок | F49: 6,6 | G49: 7,5 | H49: - | I49: - | J49: 895×307×235 | K49: 12.8 | L49: 6,35 / 15,88 | M49: - | N49: =VLOOKUP(C49,Лист1!$A$1:$D$130,4,FALSE) -> 75100 | O49: =VLOOKUP(C49,Лист1!$A$1:$D$130,3,FALSE) -> 64256 | P49: =O49*(1-$P$2) -> 64256
B50: Внутренние блоки мульти сплит-систем настенного типа серии ARTCOOL Mirror
A56: НС-1606433 | B56: 9k | C56: НС-1606433 | D56: AC09BK.NSJR | E56: внутренний блок | F56: 2,5 | G56: 3,3 | H56: - | I56: - | J56: 837×308×189 | K56: 9.9 | L56: 6,35 / 9,52 | M56: - | N56: =VLOOKUP(C56,Лист1!$A$1:$D$130,4,FALSE) -> 39000 | O56: =VLOOKUP(C56,Лист1!$A$1:$D$130,3,FALSE) -> 33043 | P56: =O56*(1-$P$2) -> 33043
A57: НС-1606436 | B57: 12k | C57: НС-1606436 | D57: AC12BK.NSJR | E57: внутренний блок | F57: 3.5 | G57: 4,0 | H57: - | I57: - | J57: 837×308×189 | K57: 9.9 | L57: 6,35 / 9,52 | M57: - | N57: =VLOOKUP(C57,Лист1!$A$1:$D$130,4,FALSE) -> 40900 | O57: =VLOOKUP(C57,Лист1!$A$1:$D$130,3,FALSE) -> 34975 | P57: =O57*(1-$P$2) -> 34975
B58: Внутренние блоки мульти сплит-систем настенного типа серии ARTCOOL Gallery
A64: НС-1724225 | B64: 9k | C64: НС-1724225 | D64: A09GA1.NSER | E64: внутренний блок | F64: 2,6 | G64: 3,7 | H64: - | I64: - | J64: 652×652×158 | K64: 16.7 | L64: 6,35 / 9,52 | M64: - | N64: =VLOOKUP(C64,Лист1!$A$1:$D$130,4,FALSE) -> 79900 | O64: =VLOOKUP(C64,Лист1!$A$1:$D$130,3,FALSE) -> 66899 | P64: =O64*(1-$P$2) -> 66899
A65: НС-1724226 | B65: 12k | C65: НС-1724226 | D65: A12GA1.NSER | E65: внутренний блок | F65: 3,7 | G65: 4,0 | H65: - | I65: - | J65: 652×652×158 | K65: 16.7 | L65: 6,35 / 9,52 | M65: - | N65: =VLOOKUP(C65,Лист1!$A$1:$D$130,4,FALSE) -> 82500 | O65: =VLOOKUP(C65,Лист1!$A$1:$D$130,3,FALSE) -> 69034 | P65: =O65*(1-$P$2) -> 69034
B66: Внутренние блоки мульти сплит-систем однопоточного кассетного типа
A72: НС-1423017 | B72: 9k | C72: НС-1423017 | D72: MT09R.NU1 | E72: внутренний блок | F72: 2,6 | G72: 2,9 | H72: - | I72: - | J72: 860×132×450 | K72: 16.1 | L72: 6,35 / 9,52 | M72: - | N72: =VLOOKUP(C72,Лист1!$A$1:$D$130,4,FALSE) -> 71600 | O72: =VLOOKUP(C72,Лист1!$A$1:$D$130,3,FALSE) -> 59884 | P72: =O72*(1-$P$2) -> 59884
A73: НС-1606407 | B73: 12k | C73: НС-1606407 | D73: MT11R.NU1 | E73: внутренний блок | F73: 3.5 | G73: 3,9 | H73: - | I73: - | J73: 860×132×450 | K73: 16.1 | L73: 6,35 / 9,52 | M73: - | N73: =VLOOKUP(C73,Лист1!$A$1:$D$130,4,FALSE) -> 75200 | O73: =VLOOKUP(C73,Лист1!$A$1:$D$130,3,FALSE) -> 62934 | P73: =O73*(1-$P$2) -> 62934
A74: НС-1606414 | C74: НС-1606414 | D74: PT-UAHG0.ENCXGLO | F74: Панель для однопоточной кассеты | N74: =VLOOKUP(C74,Лист1!$A$1:$D$130,4,FALSE) -> 21000 | O74: =VLOOKUP(C74,Лист1!$A$1:$D$130,3,FALSE) -> 17589 | P74: =O74*(1-$P$2) -> 17589
A75: НС-1340917 | C75: НС-1340917 | D75: PWLSSB21H.ENCXLEU | F75: Беспроводной пульт | N75: =VLOOKUP(C75,Лист1!$A$1:$D$130,4,FALSE) -> 16900 | O75: =VLOOKUP(C75,Лист1!$A$1:$D$130,3,FALSE) -> 14133 | P75: =O75*(1-$P$2) -> 14133
A76: НС-1275535 | C76: НС-1275535 | D76: PWFMDD200.ENCXLEU | F76: Wi-Fi модуль | N76: =VLOOKUP(C76,Лист1!$A$1:$D$130,4,FALSE) -> 10900 | O76: =VLOOKUP(C76,Лист1!$A$1:$D$130,3,FALSE) -> 9151 | P76: =O76*(1-$P$2) -> 9151

Sheet Краткий прайс
B2: =Лист1!H1 -> 46023 | O2: Ваша скидка | P2: 0
B4: СПЛИТ-СИСТЕМЫ
A5: НС-код комплект | B5: Модель | C5: НС-код блок | D5: Наименование | F5: Мощность, кВт | H5: Уровень звукового давления ВБ | I5: Класс энерго-эффективности | J5: Габариты блока (ДхВхГ), мм | K5: Вес нетто, (кг) | L5: РИЦ, руб. | M5: Дилерская цена, руб. | N5: Ваша спец. цена, руб.
F6: охлаждение | G6: нагрев
B7: Deluxe Pro
A8: НС-1697698 | B8: 9K | C8: НС-1697689 | D8: H09S1D.NS1R | E8: внутренний блок | F8: 2,50 (0,89 - 3,8) | G8: 3,2 (0,65 - 4,9) | H8: 19/27/35/40/47 | I8: A+++/А++ | J8: 895×307×235 | K8: 11 | L8: =VLOOKUP(C8,Лист1!$A$1:$D$130,4,FALSE)+VLOOKUP(C9,Лист1!$A$1:$D$130,4,FALSE) -> 89990 | M8: =VLOOKUP(C8,Лист1!$A$1:$D$130,3,FALSE)+VLOOKUP(C9,Лист1!$A$1:$D$130,3,FALSE) -> 74119 | N8: =M8*(1-$P$2) -> 74119
C9: НС-1697691 | D9: H09S1D.U12R | E9: наружный блок | J9: 717×495×230 | K9: 25.1
A10: НС-1697699 | B10: 12K | C10: НС-1697692 | D10: H12S1D.NS1R | E10: внутренний блок | F10: 3,5 (0,89 - 4,2) | G10: 4,0 (0,65 - 5,4) | H10: 19/27/35/40/47 | I10: A+++/А++ | J10: 895×307×235 | K10: 11 | L10: =VLOOKUP(C10,Лист1!$A$1:$D$130,4,FALSE)+VLOOKUP(C11,Лист1!$A$1:$D$130,4,FALSE) -> 108990 | M10: =VLOOKUP(C10,Лист1!$A$1:$D$130,3,FALSE)+VLOOKUP(C11,Лист1!$A$1:$D$130,3,FALSE) -> 90386 | N10: =M10*(1-$P$2) -> 90386
C11: НС-1697693 | D11: H12S1D.U12R | E11: наружный блок | J11: 717×495×230 | K11: 25.1
A12: НС-1697700 | B12: 18K | C12: НС-1697694 | D12: H18S1D.NS1R | E12: внутренний блок | F12: 5,0 (0,9 - 5,5) | G12: 5,8 (0,9 - 6,40) | H12: 29/34/39/44/49 | I12: A++/А+ | J12: 895×307×235 | K12: 12.8 | L12: =VLOOKUP(C12,Лист1!$A$1:$D$130,4,FALSE)+VLOOKUP(C13,Лист1!$A$1:$D$130,4,FALSE) -> 154990 | M12: =VLOOKUP(C12,Лист1!$A$1:$D$130,3,FALSE)+VLOOKUP(C13,Лист1!$A$1:$D$130,3,FALSE) -> 132071 | N12: =M12*(1-$P$2) -> 132071
C13: НС-1697695 | D13: H18S1D.U18R | E13: наружный блок | J13: 770×545×288 | K13: 34.4
A14: НС-1697701 | B14: 24K | C14: НС-1697696 | D14: H24S1D.NS1R | E14: внутренний блок | F14: 6,6 (0,9 - 7,72) | G14: 7,5 (0,9 - 8,64) | H14: 31/34/42/47/51 | I14: A++/А+ | J14: 895×307×235 | K14: 12.8 | L14: =VLOOKUP(C14,Лист1!$A$1:$D$130,4,FALSE)+VLOOKUP(C15,Лист1!$A$1:$D$130,4,FALSE) -> 189990 | M14: =VLOOKUP(C14,Лист1!$A$1:$D$130,3,FALSE)+VLOOKUP(C15,Лист1!$A$1:$D$130,3,FALSE) -> 162571 | N14: =M14*(1-$P$2) -> 162571
C15: НС-1697697 | D15: H24S1D.U24R | E15: наружный блок | J15: 870×650×330 | K15: 44
B16: ARTCOOL Mirror
A17: НС-1606456 | B17: 9K | C17: НС-1606433 | D17: AC09BK.NSJR | E17: внутренний блок | F17: 2,50 (0,89 - 3,70) | G17: 3,3 (0,89 - 4,10) | H17: 19/27/35/45 | I17: A++/А+ | J17: 837х308х189 | K17: 9.9 | L17: =VLOOKUP(C17,Лист1!$A$1:$D$130,4,FALSE)+VLOOKUP(C18,Лист1!$A$1:$D$130,4,FALSE) -> 92990 | M17: =VLOOKUP(C17,Лист1!$A$1:$D$130,3,FALSE)+VLOOKUP(C18,Лист1!$A$1:$D$130,3,FALSE) -> 78897 | N17: =M17*(1-$P$2) -> 78897
C18: НС-1606434 | D18: AC09BK.UA3R | E18: наружный блок | J18: 717×483×230 | K18: 26
A19: НС-1606457 | B19: 12K | C19: НС-1606436 | D19: AC12BK.NSJR | E19: внутренний блок | F19: 3,5 (0,89 - 4,04) | G19: 4,0 (0,89 - 5,10) | H19: 19/27/35/45 | I19: A++/А+ | J19: 837х308х189 | K19: 9.9 | L19: =VLOOKUP(C19,Лист1!$A$1:$D$130,4,FALSE)+VLOOKUP(C20,Лист1!$A$1:$D$130,4,FALSE) -> 97990 | M19: =VLOOKUP(C19,Лист1!$A$1:$D$130,3,FALSE)+VLOOKUP(C20,Лист1!$A$1:$D$130,3,FALSE) -> 83879 | N19: =M19*(1-$P$2) -> 83879
C20: НС-1606438 | D20: AC12BK.UA3R | E20: наружный блок | J20: 717×483×230 | K20: 26
B21: ProCool
A22: НС-1344689 | B22: 7K | C22: НС-1198217 | D22: B07TS.NSJ | E22: внутренний блок | F22: 2,14 (0,88-3,05) | G22: 2,50 (0,88-4,04) | H22: 19/28/32/36 | I22: A/А | J22: 837х308х189 | K22: 8.6 | L22: =VLOOKUP(C22,Лист1!$A$1:$D$130,4,FALSE)+VLOOKUP(C23,Лист1!$A$1:$D$130,4,FALSE) -> 59990 | M22: =VLOOKUP(C22,Лист1!$A$1:$D$130,3,FALSE)+VLOOKUP(C23,Лист1!$A$1:$D$130,3,FALSE) -> 48701 | N22: =M22*(1-$P$2) -> 48701
C23: НС-1198218 | D23: B07TS.UA3 | E23: наружный блок | J23: 717×495×230 | K23: 26.4
A24: НС-1344693 | B24: 9K | C24: НС-1198219 | D24: B09TS.NSJ | E24: внутренний блок | F24: 2,70 (0,88-3,46) | G24: 2,93 (0,88-4,04) | H24: 19/28/36/42 | I24: A/А | J24: 837х308х189 | K24: 8.6 | L24: =VLOOKUP(C24,Лист1!$A$1:$D$130,4,FALSE)+VLOOKUP(C25,Лист1!$A$1:$D$130,4,FALSE) -> 64990 | M24: =VLOOKUP(C24,Лист1!$A$1:$D$130,3,FALSE)+VLOOKUP(C25,Лист1!$A$1:$D$130,3,FALSE) -> 52768 | N24: =M24*(1-$P$2) -> 52768
C25: НС-1198221 | D25: B09TS.UA3 | E25: наружный блок | J25: 717×495×230 | K25: 26.4
A26: НС-1344695 | B26: 12K | C26: НС-1198222 | D26: B12TS.NSJ | E26: внутренний блок | F26: 3,52 (0,88-3,87) | G26: 3,52 (0,88-4,04) | H26: 19/28/36/42 | I26: A/А | J26: 837х308х189 | K26: 8.6 | L26: =VLOOKUP(C26,Лист1!$A$1:$D$130,4,FALSE)+VLOOKUP(C27,Лист1!$A$1:$D$130,4,FALSE) -> 72990 | M26: =VLOOKUP(C26,Лист1!$A$1:$D$130,3,FALSE)+VLOOKUP(C27,Лист1!$A$1:$D$130,3,FALSE) -> 59885 | N26: =M26*(1-$P$2) -> 59885
C27: НС-1198224 | D27: B12TS.UA3 | E27: наружный блок | J27: 717×495×230 | K27: 26.4
A28: НС-1347782 | B28: 18K | C28: НС-1198226 | D28: B18TS.NSK | E28: внутренний блок | F28: 5,28 (1,08-5,36) | G28: 5,42 (1,08-6,10) | H28: 32/38/43/55 | I28: A/А | J28: 998x345x210 | K28: 11.5 | L28: =VLOOKUP(C28,Лист1!$A$1:$D$130,4,FALSE)+VLOOKUP(C29,Лист1!$A$1:$D$130,4,FALSE) -> 99990 | M28: =VLOOKUP(C28,Лист1!$A$1:$D$130,3,FALSE)+VLOOKUP(C29,Лист1!$A$1:$D$130,3,FALSE) -> 82252 | N28: =M28*(1-$P$2) -> 82252
C29: НС-1198227 | D29: B18TS.UL2 | E29: наружный блок | J29: 770x545x288 | K29: 34.2
A30: НС-1347783 | B30: 24K | C30: НС-1374053 | D30: B24TS.NSKC | E30: внутренний блок | F30: 6,45 (1,03-7,18) | G30: 6,45 (1,03-7,18) | H30: 32/38/43/56 | I30: A/B | J30: 998x345x210 | K30: 13 | L30: =VLOOKUP(C30,Лист1!$A$1:$D$130,4,FALSE)+VLOOKUP(C31,Лист1!$A$1:$D$130,4,FALSE) -> 119990 | M30: =VLOOKUP(C30,Лист1!$A$1:$D$130,3,FALSE)+VLOOKUP(C31,Лист1!$A$1:$D$130,3,FALSE) -> 101570 | N30: =M30*(1-$P$2) -> 101570
C31: НС-1374054 | D31: B24TS.U24C | E31: наружный блок | J31: 870x650x330 | K31: 42.7
B32: MegaCool
A33: НС-1606451 | B33: 7K | C33: НС-1606371 | D33: P07EP2.NSAR | E33: внутренний блок | F33: 2,14 (0,88-3,05) | G33: 2,50 (0,88-3,70) | H33: 21/28/36/42 | I33: A/А | J33: 754×308×189 | K33: 7.8 | L33: =VLOOKUP(C33,Лист1!$A$1:$D$130,4,FALSE)+VLOOKUP(C34,Лист1!$A$1:$D$130,4,FALSE) -> 42990 | M33: =VLOOKUP(C33,Лист1!$A$1:$D$130,3,FALSE)+VLOOKUP(C34,Лист1!$A$1:$D$130,3,FALSE) -> 30299 | N33: =M33 -> 30299
C34: НС-1606373 | D34: P07EP2.UA3R | E34: наружный блок | J34: 717×495×230 | K34: 25.7
A35: НС-1606452 | B35: 9K | C35: НС-1606374 | D35: P09EP2.NSAR | E35: внутренний блок | F35: 2,64 (0,88-3,25) | G35: 2,70 (0,88-3,70) | H35: 21/28/36/42 | I35: A/А | J35: 754×308×189 | K35: 7.8 | L35: =VLOOKUP(C35,Лист1!$A$1:$D$130,4,FALSE)+VLOOKUP(C36,Лист1!$A$1:$D$130,4,FALSE) -> 45990 | M35: =VLOOKUP(C35,Лист1!$A$1:$D$130,3,FALSE)+VLOOKUP(C36,Лист1!$A$1:$D$130,3,FALSE) -> 31417 | N35: =M35 -> 31417
C36: НС-1606375 | D36: P09EP2.UA3R | E36: наружный блок | J36: 717×495×230 | K36: 25.7
A37: НС-1606454 | B37: 18K | C37: НС-1606384 | D37: P18EP1.NSK | E37: внутренний блок | F37: 5,28 (1,08-5,36) | G37: 5,42 (1,08-6,10) | H37: 32/38/43/55 | I37: A/А | J37: 998x345x210 | K37: 11.4 | L37: =VLOOKUP(C37,Лист1!$A$1:$D$130,4,FALSE)+VLOOKUP(C38,Лист1!$A$1:$D$130,4,FALSE) -> 79990 | M37: =VLOOKUP(C37,Лист1!$A$1:$D$130,3,FALSE)+VLOOKUP(C38,Лист1!$A$1:$D$130,3,FALSE) -> 57139 | N37: =M37 -> 57139
C38: НС-1606385 | D38: P18EP1.UL2 | E38: наружный блок | J38: 770x545x288 | K38: 34
A39: НС-1606455 | B39: 24K | C39: НС-1606386 | D39: P24EP.NSKC | E39: внутренний блок | F39: 6,45 (1,03-7,18) | G39: 6,45 (1,03-7,18) | H39: 32/38/43/48 | I39: A/B | J39: 998x345x210 | K39: 11.7 | L39: =VLOOKUP(C39,Лист1!$A$1:$D$130,4,FALSE)+VLOOKUP(C40,Лист1!$A$1:$D$130,4,FALSE) -> 99990 | M39: =VLOOKUP(C39,Лист1!$A$1:$D$130,3,FALSE)+VLOOKUP(C40,Лист1!$A$1:$D$130,3,FALSE) -> 69645 | N39: =M39 -> 69645
C40: НС-1606393 | D40: P24EP.U24C | E40: наружный блок | J40: 870x650x330 | K40: 42.9
B42: МУЛЬТИ СПЛИТ-СИСТЕМЫ R32
A43: НС-код комплект | B43: Модель | C43: НС-код блок | D43: Блок | E43: Тип блока | F43: Мощность, кВт | H43: SEER | I43: SCOP | J43: Габариты блока (ДхВхГ), мм | K43: Вес, кг | L43: Диаметры труб, мм | M43: ВБ: Кол-во (Мощность), кВт мин./макс. | N43: РИЦ, руб. | O43: Дилерская цена, руб. | P43: Ваша спец. цена, руб.
...
